Workbook

Sheet Data
A1: Period | B1: Trade Flow | C1: Reporter | D1: Partner | E1: Commodity Code | F1: Trade Value (US) | G1: Net Weight(kg) | H1: Export Prices (Country) | I1: Export Prices (World) | J1: Export Share | K1: GPR_importer | L1: Producer Prices | M1: GPR_exporter | N1: GPR_importer_std | O1: GPR_world | P1: Import Share | Q1: Pol Stab_importer | R1: Pol Stab_exporter | W1: Source: Period, Trade Flow, Reporter, Partner, Commodity Code, Net Weight: UN comtrade: https://comtradeplus.un.org/
A2: 202506 | B2: X | C2: India | D2: Mauritius | E2: 80450 | F2: 10906 | G2: 4886 | H2: =F2/G2 -> 2.2320917 | I2: 1.4290057 | J2: 0.0007729132 | K2: 220.12001 | M2: 0.46758103 | N2: =(K2-$S$2)/$S$3 -> 2.9757509 | O2: =VLOOKUP(A2,$T$5:$U$158,2,FALSE) -> 220.12001 | P2: 0.7498 | S2: =AVERAGE(K2:K89) -> 110.18764 | W2: Source: Producer Prices: https://www.fao.org/faostat/en/#data/PP
A3: 202505 | B3: X | C3: India | D3: Mauritius | E3: 80450 | F3: 38296 | G3: 11698 | H3: =F3/G3 -> 3.273722 | I3: 1.5528386 | J3: 0.001347516 | K3: 165.22462 | M3: 0.76241863 | N3: =(K3-$S$2)/$S$3 -> 1.4897919 | O3: =VLOOKUP(A3,$T$5:$U$158,2,FALSE) -> 165.22462 | P3: 0.823 | S3: =_xlfn.STDEV.S(K2:K89) -> 36.942735 | W3: Source: GPR_importer, exporter, world: https://www.matteoiacoviello.com/gpr.htm
A4: 202504 | B4: X | C4: India | D4: Mauritius | E4: 80450 | F4: 38615 | G4: 44254 | H4: =F4/G4 -> 0.87257649 | I4: 1.6721507 | J4: 0.0012407355 | K4: 140.5289 | M4: 0.42514426 | N4: =(K4-$S$2)/$S$3 -> 0.82130531 | O4: =VLOOKUP(A4,$T$5:$U$158,2,FALSE) -> 140.5289 | P4: 0.8534
A5: 202503 | B5: X | C5: India | D5: Mauritius | E5: 80450 | F5: 36406 | G5: 42254 | H5: =F5/G5 -> 0.8615989 | I5: 1.5056713 | J5: 0.0023445984 | K5: 171.87291 | M5: 0.24915466 | N5: =(K5-$S$2)/$S$3 -> 1.6697539 | O5: =VLOOKUP(A5,$T$5:$U$158,2,FALSE) -> 171.87291 | P5: 0.9337 | T5: 201301 | U5: 90.657494
A6: 202412 | B6: X | C6: India | D6: Mauritius | E6: 80450 | F6: 59559 | G6: 49700 | H6: =F6/G6 -> 1.1983702 | I6: 1.2264705 | J6: 0.0055486197 | K6: 141.90271 | L6: 833.3 | M6: 0.19472842 | N6: =(K6-$S$2)/$S$3 -> 0.85849286 | O6: =VLOOKUP(A6,$T$5:$U$158,2,FALSE) -> 141.90271 | P6: 0.9072 | T6: 201302 | U6: 81.590332
A7: 202411 | B7: X | C7: India | D7: Mauritius | E7: 80450 | F7: 21515 | G7: 20806 | H7: =F7/G7 -> 1.0340767 | I7: 1.1506152 | J7: 0.0022369108 | K7: 128.48177 | L7: 833.3 | M7: 0.18260814 | N7: =(K7-$S$2)/$S$3 -> 0.49520237 | O7: =VLOOKUP(A7,$T$5:$U$158,2,FALSE) -> 128.48177 | P7: 0.8296 | T7: 201303 | U7: 75.896721
A8: 202410 | B8: X | C8: India | D8: Mauritius | E8: 80450 | F8: 19406 | G8: 7668 | H8: =F8/G8 -> 2.5307773 | I8: 1.3245168 | J8: 0.0017317842 | K8: 130.68921 | L8: 833.3 | M8: 0.2658588 | N8: =(K8-$S$2)/$S$3 -> 0.55495548 | O8: =VLOOKUP(A8,$T$5:$U$158,2,FALSE) -> 130.68921 | P8: 1 | T8: 201304 | U8: 95.107872
A9: 202409 | B9: X | C9: India | D9: Mauritius | E9: 80450 | F9: 3175 | G9: 1224 | H9: =F9/G9 -> 2.5939542 | I9: 1.4878749 | J9: 0.00042198389 | K9: 130.14188 | L9: 833.3 | M9: 0.1691497 | N9: =(K9-$S$2)/$S$3 -> 0.54013977 | O9: =VLOOKUP(A9,$T$5:$U$158,2,FALSE) -> 130.14188 | P9: 0.158 | T9: 201305 | U9: 83.717316
A10: 202408 | B10: X | C10: India | D10: Mauritius | E10: 80450 | F10: 16263 | G10: 6242 | H10: =F10/G10 -> 2.6054149 | I10: 1.2541433 | J10: 0.0016740648 | K10: 140.76402 | L10: 833.3 | M10: 0.22787695 | N10: =(K10-$S$2)/$S$3 -> 0.82766983 | O10: =VLOOKUP(A10,$T$5:$U$158,2,FALSE) -> 140.76402 | P10: 0.1081 | T10: 201306 | U10: 82.973007
A11: 202407 | B11: X | C11: India | D11: Mauritius | E11: 80450 | F11: 4249 | G11: 1323 | H11: =F11/G11 -> 3.2116402 | I11: 0.97456242 | J11: 0.00046806614 | K11: 92.394875 | L11: 833.3 | M11: 0.16011824 | N11: =(K11-$S$2)/$S$3 -> -0.48163087 | O11: =VLOOKUP(A11,$T$5:$U$158,2,FALSE) -> 92.394875 | P11: 0.0041 | T11: 201307 | U11: 73.975815
A12: 202406 | B12: X | C12: India | D12: Mauritius | E12: 80450 | F12: 6520 | G12: 2009 | H12: =F12/G12 -> 3.2453957 | I12: 1.6192706 | J12: 0.000453261 | K12: 112.88141 | L12: 833.3 | M12: 0.19021051 | N12: =(K12-$S$2)/$S$3 -> 0.072917522 | O12: =VLOOKUP(A12,$T$5:$U$158,2,FALSE) -> 112.88141 | P12: 0.4913 | T12: 201308 | U12: 90.956749
A13: 202405 | B13: X | C13: India | D13: Mauritius | E13: 80450 | F13: 16333 | G13: 5636 | H13: =F13/G13 -> 2.8979773 | I13: 1.7477125 | J13: 0.000558885 | K13: 130.52187 | L13: 833.3 | M13: 0.13457304 | N13: =(K13-$S$2)/$S$3 -> 0.55042568 | O13: =VLOOKUP(A13,$T$5:$U$158,2,FALSE) -> 130.52187 | P13: 0.6762 | T13: 201309 | U13: 100.45933
A14: 202311 | B14: X | C14: India | D14: Mauritius | E14: 80450 | F14: 6290 | G14: 2550 | H14: =F14/G14 -> 2.4666667 | I14: 1.2431354 | J14: 0.0014863876 | K14: 156.69614 | L14: 825.6 | M14: 0.25032857 | N14: =(K14-$S$2)/$S$3 -> 1.258935 | O14: =VLOOKUP(A14,$T$5:$U$158,2,FALSE) -> 156.69614 | P14: 0.771 | Q14: 0.78 | R14: -0.64 | T14: 201310 | U14: 72.953117
A15: 202310 | B15: X | C15: India | D15: Mauritius | E15: 80450 | F15: 3177 | G15: 1224 | H15: =F15/G15 -> 2.5955882 | I15: 1.2663608 | J15: 0.00041250585 | K15: 197.88701 | L15: 825.6 | M15: 0.22093509 | N15: =(K15-$S$2)/$S$3 -> 2.3739275 | O15: =VLOOKUP(A15,$T$5:$U$158,2,FALSE) -> 197.88701 | P15: 0.4067 | Q15: 0.78 | R15: -0.64 | T15: 201311 | U15: 77.779022
A16: 202309 | B16: X | C16: India | D16: Mauritius | E16: 80450 | F16: 2504 | G16: 1071 | H16: =F16/G16 -> 2.3380019 | I16: 1.1297711 | J16: 0.00028526419 | K16: 98.634811 | L16: 825.6 | M16: 0.45979792 | N16: =(K16-$S$2)/$S$3 -> -0.31272251 | O16: =VLOOKUP(A16,$T$5:$U$158,2,FALSE) -> 98.634811 | P16: 0.078 | Q16: 0.78 | R16: -0.64 | T16: 201312 | U16: 70.37249
A17: 202307 | B17: X | C17: India | D17: Mauritius | E17: 80450 | F17: 4317 | G17: 1134 | H17: =F17/G17 -> 3.8068783 | I17: 1.0581756 | J17: 0.00028265037 | K17: 107.44878 | L17: 825.6 | M17: 0.21112767 | N17: =(K17-$S$2)/$S$3 -> -0.074137775 | O17: =VLOOKUP(A17,$T$5:$U$158,2,FALSE) -> 107.44878 | P17: 0.0957 | Q17: 0.78 | R17: -0.64 | T17: 201401 | U17: 77.91597
A18: 202306 | B18: X | C18: India | D18: Mauritius | E18: 80450 | F18: 12727 | G18: 3355 | H18: =F18/G18 -> 3.7934426 | I18: 1.545201 | J18: 0.00071689038 | K18: 110.52895 | L18: 825.6 | M18: 0.26301304 | N18: =(K18-$S$2)/$S$3 -> 0.0092388909 | O18: =VLOOKUP(A18,$T$5:$U$158,2,FALSE) -> 110.52895 | P18: 0.612 | Q18: 0.78 | R18: -0.64 | T18: 201402 | U18: 69.003525
A19: 202305 | B19: X | C19: India | D19: Mauritius | E19: 80450 | F19: 25971 | G19: 6124 | H19: =F19/G19 -> 4.2408556 | I19: 1.6160682 | J19: 0.00097985463 | K19: 108.46768 | L19: 825.6 | M19: 0.31503695 | N19: =(K19-$S$2)/$S$3 -> -0.046557304 | O19: =VLOOKUP(A19,$T$5:$U$158,2,FALSE) -> 108.46768 | P19: 1 | Q19: 0.78 | R19: -0.64 | T19: 201403 | U19: 119.83855
A20: 202304 | B20: X | C20: India | D20: Mauritius | E20: 80450 | F20: 421 | G20: 148 | H20: =F20/G20 -> 2.8445946 | I20: 1.7850799 | J20: 2.2257445e-05 | K20: 106.80965 | L20: 825.6 | M20: 0.2464332 | N20: =(K20-$S$2)/$S$3 -> -0.091438326 | O20: =VLOOKUP(A20,$T$5:$U$158,2,FALSE) -> 106.80965 | P20: 0.1039 | Q20: 0.78 | R20: -0.64 | T20: 201404 | U20: 93.221542
A21: 202303 | B21: X | C21: India | D21: Mauritius | E21: 80450 | F21: 3986 | G21: 1530 | H21: =F21/G21 -> 2.6052288 | I21: 1.6928368 | J21: 0.00024389459 | K21: 105.37997 | L21: 825.6 | M21: 0.30663994 | N21: =(K21-$S$2)/$S$3 -> -0.13013822 | O21: =VLOOKUP(A21,$T$5:$U$158,2,FALSE) -> 105.37997 | P21: 0.7509 | Q21: 0.78 | R21: -0.64 | T21: 201405 | U21: 83.428856
A22: 202302 | B22: X | C22: India | D22: Mauritius | E22: 80450 | F22: 17032 | G22: 5584 | H22: =F22/G22 -> 3.0501433 | I22: 1.3625965 | J22: 0.0017104202 | K22: 120.99438 | L22: 825.6 | M22: 0.29352903 | N22: =(K22-$S$2)/$S$3 -> 0.29252683 | O22: =VLOOKUP(A22,$T$5:$U$158,2,FALSE) -> 120.99438 | P22: 0.8874 | Q22: 0.78 | R22: -0.64 | T22: 201406 | U22: 98.767105
A23: 202211 | B23: X | C23: India | D23: Mauritius | E23: 80450 | F23: 4549 | G23: 1841 | H23: =F23/G23 -> 2.4709397 | I23: 1.3706627 | J23: 0.00028359255 | K23: 116.71629 | L23: 843.6 | M23: 0.29648212 | N23: =(K23-$S$2)/$S$3 -> 0.17672351 | O23: =VLOOKUP(A23,$T$5:$U$158,2,FALSE) -> 116.71629 | P23: 0.9092 | Q23: 0.83 | R23: -0.62 | T23: 201407 | U23: 138.75395
A24: 202210 | B24: X | C24: India | D24: Mauritius | E24: 80450 | F24: 23 | G24: 9 | H24: =F24/G24 -> 2.5555556 | I24: 1.3232739 | J24: 1.3518735e-06 | K24: 143.16241 | L24: 843.6 | M24: 0.30671361 | N24: =(K24-$S$2)/$S$3 -> 0.89259171 | O24: =VLOOKUP(A24,$T$5:$U$158,2,FALSE) -> 143.16241 | P24: 0.0015 | Q24: 0.83 | R24: -0.62 | T24: 201408 | U24: 136.44559
A25: 202209 | B25: X | C25: India | D25: Mauritius | E25: 80450 | F25: 39448 | G25: 22780 | H25: =F25/G25 -> 1.7316945 | I25: 1.3487115 | J25: 0.0015017903 | K25: 131.98587 | L25: 843.6 | M25: 0.50662738 | N25: =(K25-$S$2)/$S$3 -> 0.5900547 | O25: =VLOOKUP(A25,$T$5:$U$158,2,FALSE) -> 131.98587 | P25: 0.8456 | Q25: 0.83 | R25: -0.62 | T25: 201409 | U25: 131.55666
... A89: 201302 | B89: X | C89: India | D89: Mauritius | E89: 80450 | F89: 860 | G89: 1000 | H89: =F89/G89 -> 0.86 | I89: 0.86039048 | J89: 8.5896177e-05 | K89: 81.590332 | L89: 713.7 | M89: 0.11446615 | N89: =(K89-$S$2)/$S$3 -> -0.77409819 | O89: =VLOOKUP(A89,$T$5:$U$158,2,FALSE) -> 81.590332 | P89: 0.3549 | Q89: 0.94 | R89: -1.23 | T89: 202001 | U89: 138.42094
A90: 202506 | B90: X | C90: India | D90: South Africa | E90: 80450 | F90: 12656 | G90: 5150 | H90: =F90/G90 -> 2.4574757 | I90: 1.4290057 | J90: 0.0008969365 | K90: 0.049875312 | M90: 0.46758103 | N90: =(K90-$S$90)/$S$91 -> -0.19286518 | O90: =VLOOKUP(A90,$T$5:$U$158,2,FALSE) -> 220.12001 | P90: 0.116 | Q90: 0.94 | R90: -1.23 | S90: =AVERAGE(K90:K233) -> 0.058129436 | T90: 202002 | U90: 75.955559
A91: 202505 | B91: X | C91: India | D91: South Africa | E91: 80450 | F91: 11332 | G91: 5132 | H91: =F91/G91 -> 2.208106 | I91: 1.5528386 | J91: 0.00039873751 | K91: 0.093836136 | M91: 0.76241863 | N91: =(K91-$S$90)/$S$91 -> 0.83431979 | O91: =VLOOKUP(A91,$T$5:$U$158,2,FALSE) -> 165.22462 | P91: 0.2263 | S91: =_xlfn.STDEV.S(K90:K233) -> 0.042797379 | T91: 202003 | U91: 81.540031
A92: 202504 | B92: X | C92: India | D92: South Africa | E92: 80450 | F92: 2139 | G92: 781 | H92: =F92/G92 -> 2.7387964 | I92: 1.6721507 | J92: 6.8728039e-05 | K92: 0.1153963 | M92: 0.42514426 | N92: =(K92-$S$90)/$S$91 -> 1.3380927 | O92: =VLOOKUP(A92,$T$5:$U$158,2,FALSE) -> 140.5289 | P92: 0.9912 | T92: 202004 | U92: 69.339401
A93: 202503 | B93: X | C93: India | D93: South Africa | E93: 80450 | F93: 16427 | G93: 8776 | H93: =F93/G93 -> 1.8718095 | I93: 1.5056713 | J93: 0.0010579223 | K93: 0.083051555 | M93: 0.24915466 | N93: =(K93-$S$90)/$S$91 -> 0.58232816 | O93: =VLOOKUP(A93,$T$5:$U$158,2,FALSE) -> 171.87291 | P93: 1 | T93: 202005 | U93: 68.507217
A94: 202502 | B94: X | C94: India | D94: South Africa | E94: 80450 | F94: 101958 | G94: 134550 | H94: =F94/G94 -> 0.75777035 | I94: 1.3750398 | J94: 0.010646738 | K94: 0.074153967 | M94: 0.20897937 | N94: =(K94-$S$90)/$S$91 -> 0.37442787 | O94: =VLOOKUP(A94,$T$5:$U$158,2,FALSE) -> 136.20163 | P94: 0.9401 | T94: 202006 | U94: 71.227859
A95: 202501 | B95: X | C95: India | D95: South Africa | E95: 80450 | F95: 18862 | G95: 8792 | H95: =F95/G95 -> 2.1453594 | I95: 1.2166639 | J95: 0.0025808563 | K95: 0.081560954 | M95: 0.23840894 | N95: =(K95-$S$90)/$S$91 -> 0.54749891 | O95: =VLOOKUP(A95,$T$5:$U$158,2,FALSE) -> 112.32622 | P95: 0.2723 | T95: 202007 | U95: 66.473282
A96: 202412 | B96: X | C96: India | D96: South Africa | E96: 80450 | F96: 8426 | G96: 5062 | H96: =F96/G96 -> 1.6645595 | I96: 1.2264705 | J96: 0.00078498076 | K96: 0.1043188 | L96: 833.3 | M96: 0.19472842 | N96: =(K96-$S$90)/$S$91 -> 1.0792568 | O96: =VLOOKUP(A96,$T$5:$U$158,2,FALSE) -> 141.90271 | P96: 0.635 | T96: 202008 | U96: 65.466049
A97: 202411 | B97: X | C97: India | D97: South Africa | E97: 80450 | F97: 11405 | G97: 4705 | H97: =F97/G97 -> 2.424017 | I97: 1.1506152 | J97: 0.0011857759 | K97: 0.094452493 | L97: 833.3 | M97: 0.18260814 | N97: =(K97-$S$90)/$S$91 -> 0.84872153 | O97: =VLOOKUP(A97,$T$5:$U$158,2,FALSE) -> 128.48177 | P97: 0.1572 | T97: 202009 | U97: 80.37738
A98: 202410 | B98: X | C98: India | D98: South Africa | E98: 80450 | F98: 4962 | G98: 2301 | H98: =F98/G98 -> 2.1564537 | I98: 1.3245168 | J98: 0.00044280704 | K98: 0.15456906 | L98: 833.3 | M98: 0.2658588 | N98: =(K98-$S$90)/$S$91 -> 2.2534002 | O98: =VLOOKUP(A98,$T$5:$U$158,2,FALSE) -> 130.68921 | P98: 0.0366 | T98: 202010 | U98: 76.083168
A99: 202409 | B99: X | C99: India | D99: South Africa | E99: 80450 | F99: 7498 | G99: 2914 | H99: =F99/G99 -> 2.5730954 | I99: 1.4878749 | J99: 0.00099654651 | K99: 0.071563333 | L99: 833.3 | M99: 0.1691497 | N99: =(K99-$S$90)/$S$91 -> 0.31389533 | O99: =VLOOKUP(A99,$T$5:$U$158,2,FALSE) -> 130.14188 | P99: 0.1644 | T99: 202011 | U99: 70.067467
A100: 202408 | B100: X | C100: India | D100: South Africa | E100: 80450 | F100: 3560 | G100: 1751 | H100: =F100/G100 -> 2.0331239 | I100: 1.2541433 | J100: 0.00036645579 | K100: 0.069629066 | L100: 833.3 | M100: 0.22787695 | N100: =(K100-$S$90)/$S$91 -> 0.26869939 | O100: =VLOOKUP(A100,$T$5:$U$158,2,FALSE) -> 140.76402 | P100: 0.1446 | T100: 202012 | U100: 64.067291
A101: 202407 | B101: X | C101: India | D101: South Africa | E101: 80450 | F101: 12171 | G101: 6161 | H101: =F101/G101 -> 1.975491 | I101: 0.97456242 | J101: 0.0013407467 | K101: 0.055425543 | L101: 833.3 | M101: 0.16011824 | N101: =(K101-$S$90)/$S$91 -> -0.063178926 | O101: =VLOOKUP(A101,$T$5:$U$158,2,FALSE) -> 92.394875 | P101: 0.9206 | T101: 202101 | U101: 77.418701
A102: 202406 | B102: X | C102: India | D102: South Africa | E102: 80450 | F102: 2545 | G102: 2822 | H102: =F102/G102 -> 0.90184266 | I102: 1.6192706 | J102: 0.00017692473 | K102: 0.1141263 | L102: 833.3 | M102: 0.19021051 | N102: =(K102-$S$90)/$S$91 -> 1.3084181 | O102: =VLOOKUP(A102,$T$5:$U$158,2,FALSE) -> 112.88141 | P102: 1 | T102: 202102 | U102: 73.956802
A103: 202405 | B103: X | C103: India | D103: South Africa | E103: 80450 | F103: 28232 | G103: 11698 | H103: =F103/G103 -> 2.413404 | I103: 1.7477125 | J103: 0.00096604674 | K103: 0.18350868 | L103: 833.3 | M103: 0.13457304 | N103: =(K103-$S$90)/$S$91 -> 2.929601 | O103: =VLOOKUP(A103,$T$5:$U$158,2,FALSE) -> 130.52187 | P103: 0.7973 | T103: 202103 | U103: 78.618767
...

Sheet Regression
A1: Year | B1: Commodity Code | C1: Trade Value | D1: Country Dummy | E1: Post MoU Dummy | F1: MoU in Effect Dummy | G1: Export Share | H1: MoU * Export Share | I1: Export Prices (Country) | J1: Export Prices (World) | K1: Weighted Export Price | L1: GPR_importer | M1: Producer Prices | N1: GPR_exporter | O1: GPR_world | P1: Import Share | Q1: PS_exporter | R1: PS_importer | S1: MoU * Import Share
A2: =Data!A2 -> 202506 | B2: 80450 | C2: =Data!F2 -> 10906 | D2: =IF(Data!D2="Mauritius", 1, 0) -> 1 | E2: =IF(Regression!A2>201500, 1, 0) -> 1 | F2: =D2*E2 -> 1 | G2: =Data!J2 -> 0.0007729132 | H2: =F2*G2 -> 0.0007729132 | I2: =Data!H2 -> 2.2320917 | J2: =Data!I2 -> 1.4290057 | K2: =(I2*G2)+(J2*(1-G2)) -> 1.4296264 | L2: =Data!N2 -> 2.9757509 | N2: =Data!M2 -> 0.46758103 | O2: =Data!O2 -> 220.12001 | P2: =Data!P2 -> 0.7498 | S2: =P2*F2 -> 0.7498
A3: =Data!A3 -> 202505 | B3: 80450 | C3: =Data!F3 -> 38296 | D3: =IF(Data!D3="Mauritius", 1, 0) -> 1 | E3: =IF(Regression!A3>201500, 1, 0) -> 1 | F3: =D3*E3 -> 1 | G3: =Data!J3 -> 0.001347516 | H3: =F3*G3 -> 0.001347516 | I3: =Data!H3 -> 3.273722 | J3: =Data!I3 -> 1.5528386 | K3: =(I3*G3)+(J3*(1-G3)) -> 1.5551575 | L3: =Data!N3 -> 1.4897919 | N3: =Data!M3 -> 0.76241863 | O3: =Data!O3 -> 165.22462 | P3: =Data!P3 -> 0.823 | S3: =P3*F3 -> 0.823
A4: =Data!A4 -> 202504 | B4: 80450 | C4: =Data!F4 -> 38615 | D4: =IF(Data!D4="Mauritius", 1, 0) -> 1 | E4: =IF(Regression!A4>201500, 1, 0) -> 1 | F4: =D4*E4 -> 1 | G4: =Data!J4 -> 0.0012407355 | H4: =F4*G4 -> 0.0012407355 | I4: =Data!H4 -> 0.87257649 | J4: =Data!I4 -> 1.6721507 | K4: =(I4*G4)+(J4*(1-G4)) -> 1.6711586 | L4: =Data!N4 -> 0.82130531 | N4: =Data!M4 -> 0.42514426 | O4: =Data!O4 -> 140.5289 | P4: =Data!P4 -> 0.8534 | S4: =P4*F4 -> 0.8534
A5: =Data!A5 -> 202503 | B5: 80450 | C5: =Data!F5 -> 36406 | D5: =IF(Data!D5="Mauritius", 1, 0) -> 1 | E5: =IF(Regression!A5>201500, 1, 0) -> 1 | F5: =D5*E5 -> 1 | G5: =Data!J5 -> 0.0023445984 | H5: =F5*G5 -> 0.0023445984 | I5: =Data!H5 -> 0.8615989 | J5: =Data!I5 -> 1.5056713 | K5: =(I5*G5)+(J5*(1-G5)) -> 1.5041612 | L5: =Data!N5 -> 1.6697539 | N5: =Data!M5 -> 0.24915466 | O5: =Data!O5 -> 171.87291 | P5: =Data!P5 -> 0.9337 | S5: =P5*F5 -> 0.9337
A6: =Data!A6 -> 202412 | B6: 80450 | C6: =Data!F6 -> 59559 | D6: =IF(Data!D6="Mauritius", 1, 0) -> 1 | E6: =IF(Regression!A6>201500, 1, 0) -> 1 | F6: =D6*E6 -> 1 | G6: =Data!J6 -> 0.0055486197 | H6: =F6*G6 -> 0.0055486197 | I6: =Data!H6 -> 1.1983702 | J6: =Data!I6 -> 1.2264705 | K6: =(I6*G6)+(J6*(1-G6)) -> 1.2263146 | L6: =Data!N6 -> 0.85849286 | M6: =Data!L6 -> 833.3 | N6: =Data!M6 -> 0.19472842 | O6: =Data!O6 -> 141.90271 | P6: =Data!P6 -> 0.9072 | S6: =P6*F6 -> 0.9072
A7: =Data!A7 -> 202411 | B7: 80450 | C7: =Data!F7 -> 21515 | D7: =IF(Data!D7="Mauritius", 1, 0) -> 1 | E7: =IF(Regression!A7>201500, 1, 0) -> 1 | F7: =D7*E7 -> 1 | G7: =Data!J7 -> 0.0022369108 | H7: =F7*G7 -> 0.0022369108 | I7: =Data!H7 -> 1.0340767 | J7: =Data!I7 -> 1.1506152 | K7: =(I7*G7)+(J7*(1-G7)) -> 1.1503545 | L7: =Data!N7 -> 0.49520237 | M7: =Data!L7 -> 833.3 | N7: =Data!M7 -> 0.18260814 | O7: =Data!O7 -> 128.48177 | P7: =Data!P7 -> 0.8296 | S7: =P7*F7 -> 0.8296
A8: =Data!A8 -> 202410 | B8: 80450 | C8: =Data!F8 -> 19406 | D8: =IF(Data!D8="Mauritius", 1, 0) -> 1 | E8: =IF(Regression!A8>201500, 1, 0) -> 1 | F8: =D8*E8 -> 1 | G8: =Data!J8 -> 0.0017317842 | H8: =F8*G8 -> 0.0017317842 | I8: =Data!H8 -> 2.5307773 | J8: =Data!I8 -> 1.3245168 | K8: =(I8*G8)+(J8*(1-G8)) -> 1.3266057 | L8: =Data!N8 -> 0.55495548 | M8: =Data!L8 -> 833.3 | N8: =Data!M8 -> 0.2658588 | O8: =Data!O8 -> 130.68921 | P8: =Data!P8 -> 1 | S8: =P8*F8 -> 1
A9: =Data!A9 -> 202409 | B9: 80450 | C9: =Data!F9 -> 3175 | D9: =IF(Data!D9="Mauritius", 1, 0) -> 1 | E9: =IF(Regression!A9>201500, 1, 0) -> 1 | F9: =D9*E9 -> 1 | G9: =Data!J9 -> 0.00042198389 | H9: =F9*G9 -> 0.00042198389 | I9: =Data!H9 -> 2.5939542 | J9: =Data!I9 -> 1.4878749 | K9: =(I9*G9)+(J9*(1-G9)) -> 1.4883416 | L9: =Data!N9 -> 0.54013977 | M9: =Data!L9 -> 833.3 | N9: =Data!M9 -> 0.1691497 | O9: =Data!O9 -> 130.14188 | P9: =Data!P9 -> 0.158 | S9: =P9*F9 -> 0.158
A10: =Data!A10 -> 202408 | B10: 80450 | C10: =Data!F10 -> 16263 | D10: =IF(Data!D10="Mauritius", 1, 0) -> 1 | E10: =IF(Regression!A10>201500, 1, 0) -> 1 | F10: =D10*E10 -> 1 | G10: =Data!J10 -> 0.0016740648 | H10: =F10*G10 -> 0.0016740648 | I10: =Data!H10 -> 2.6054149 | J10: =Data!I10 -> 1.2541433 | K10: =(I10*G10)+(J10*(1-G10)) -> 1.2564054 | L10: =Data!N10 -> 0.82766983 | M10: =Data!L10 -> 833.3 | N10: =Data!M10 -> 0.22787695 | O10: =Data!O10 -> 140.76402 | P10: =Data!P10 -> 0.1081 | S10: =P10*F10 -> 0.1081
A11: =Data!A11 -> 202407 | B11: 80450 | C11: =Data!F11 -> 4249 | D11: =IF(Data!D11="Mauritius", 1, 0) -> 1 | E11: =IF(Regression!A11>201500, 1, 0) -> 1 | F11: =D11*E11 -> 1 | G11: =Data!J11 -> 0.00046806614 | H11: =F11*G11 -> 0.00046806614 | I11: =Data!H11 -> 3.2116402 | J11: =Data!I11 -> 0.97456242 | K11: =(I11*G11)+(J11*(1-G11)) -> 0.97560952 | L11: =Data!N11 -> -0.48163087 | M11: =Data!L11 -> 833.3 | N11: =Data!M11 -> 0.16011824 | O11: =Data!O11 -> 92.394875 | P11: =Data!P11 -> 0.0041 | S11: =P11*F11 -> 0.0041
A12: =Data!A12 -> 202406 | B12: 80450 | C12: =Data!F12 -> 6520 | D12: =IF(Data!D12="Mauritius", 1, 0) -> 1 | E12: =IF(Regression!A12>201500, 1, 0) -> 1 | F12: =D12*E12 -> 1 | G12: =Data!J12 -> 0.000453261 | H12: =F12*G12 -> 0.000453261 | I12: =Data!H12 -> 3.2453957 | J12: =Data!I12 -> 1.6192706 | K12: =(I12*G12)+(J12*(1-G12)) -> 1.6200077 | L12: =Data!N12 -> 0.072917522 | M12: =Data!L12 -> 833.3 | N12: =Data!M12 -> 0.19021051 | O12: =Data!O12 -> 112.88141 | P12: =Data!P12 -> 0.4913 | S12: =P12*F12 -> 0.4913
A13: =Data!A13 -> 202405 | B13: 80450 | C13: =Data!F13 -> 16333 | D13: =IF(Data!D13="Mauritius", 1, 0) -> 1 | E13: =IF(Regression!A13>201500, 1, 0) -> 1 | F13: =D13*E13 -> 1 | G13: =Data!J13 -> 0.000558885 | H13: =F13*G13 -> 0.000558885 | I13: =Data!H13 -> 2.8979773 | J13: =Data!I13 -> 1.7477125 | K13: =(I13*G13)+(J13*(1-G13)) -> 1.7483554 | L13: =Data!N13 -> 0.55042568 | M13: =Data!L13 -> 833.3 | N13: =Data!M13 -> 0.13457304 | O13: =Data!O13 -> 130.52187 | P13: =Data!P13 -> 0.6762 | S13: =P13*F13 -> 0.6762
A14: =Data!A14 -> 202311 | B14: 80450 | C14: =Data!F14 -> 6290 | D14: =IF(Data!D14="Mauritius", 1, 0) -> 1 | E14: =IF(Regression!A14>201500, 1, 0) -> 1 | F14: =D14*E14 -> 1 | G14: =Data!J14 -> 0.0014863876 | H14: =F14*G14 -> 0.0014863876 | I14: =Data!H14 -> 2.4666667 | J14: =Data!I14 -> 1.2431354 | K14: =(I14*G14)+(J14*(1-G14)) -> 1.244954 | L14: =Data!N14 -> 1.258935 | M14: =Data!L14 -> 825.6 | N14: =Data!M14 -> 0.25032857 | O14: =Data!O14 -> 156.69614 | P14: =Data!P14 -> 0.771 | Q14: =Data!R14 -> -0.64 | R14: =Data!Q14 -> 0.78 | S14: =P14*F14 -> 0.771
A15: =Data!A15 -> 202310 | B15: 80450 | C15: =Data!F15 -> 3177 | D15: =IF(Data!D15="Mauritius", 1, 0) -> 1 | E15: =IF(Regression!A15>201500, 1, 0) -> 1 | F15: =D15*E15 -> 1 | G15: =Data!J15 -> 0.00041250585 | H15: =F15*G15 -> 0.00041250585 | I15: =Data!H15 -> 2.5955882 | J15: =Data!I15 -> 1.2663608 | K15: =(I15*G15)+(J15*(1-G15)) -> 1.2669091 | L15: =Data!N15 -> 2.3739275 | M15: =Data!L15 -> 825.6 | N15: =Data!M15 -> 0.22093509 | O15: =Data!O15 -> 197.88701 | P15: =Data!P15 -> 0.4067 | Q15: =Data!R15 -> -0.64 | R15: =Data!Q15 -> 0.78 | S15: =P15*F15 -> 0.4067
A16: =Data!A16 -> 202309 | B16: 80450 | C16: =Data!F16 -> 2504 | D16: =IF(Data!D16="Mauritius", 1, 0) -> 1 | E16: =IF(Regression!A16>201500, 1, 0) -> 1 | F16: =D16*E16 -> 1 | G16: =Data!J16 -> 0.00028526419 | H16: =F16*G16 -> 0.00028526419 | I16: =Data!H16 -> 2.3380019 | J16: =Data!I16 -> 1.1297711 | K16: =(I16*G16)+(J16*(1-G16)) -> 1.1301158 | L16: =Data!N16 -> -0.31272251 | M16: =Data!L16 -> 825.6 | N16: =Data!M16 -> 0.45979792 | O16: =Data!O16 -> 98.634811 | P16: =Data!P16 -> 0.078 | Q16: =Data!R16 -> -0.64 | R16: =Data!Q16 -> 0.78 | S16: =P16*F16 -> 0.078
A17: =Data!A17 -> 202307 | B17: 80450 | C17: =Data!F17 -> 4317 | D17: =IF(Data!D17="Mauritius", 1, 0) -> 1 | E17: =IF(Regression!A17>201500, 1, 0) -> 1 | F17: =D17*E17 -> 1 | G17: =Data!J17 -> 0.00028265037 | H17: =F17*G17 -> 0.00028265037 | I17: =Data!H17 -> 3.8068783 | J17: =Data!I17 -> 1.0581756 | K17: =(I17*G17)+(J17*(1-G17)) -> 1.0589526 | L17: =Data!N17 -> -0.074137775 | M17: =Data!L17 -> 825.6 | N17: =Data!M17 -> 0.21112767 | O17: =Data!O17 -> 107.44878 | P17: =Data!P17 -> 0.0957 | Q17: =Data!R17 -> -0.64 | R17: =Data!Q17 -> 0.78 | S17: =P17*F17 -> 0.0957
A18: =Data!A18 -> 202306 | B18: 80450 | C18: =Data!F18 -> 12727 | D18: =IF(Data!D18="Mauritius", 1, 0) -> 1 | E18: =IF(Regression!A18>201500, 1, 0) -> 1 | F18: =D18*E18 -> 1 | G18: =Data!J18 -> 0.00071689038 | H18: =F18*G18 -> 0.00071689038 | I18: =Data!H18 -> 3.7934426 | J18: =Data!I18 -> 1.545201 | K18: =(I18*G18)+(J18*(1-G18)) -> 1.5468127 | L18: =Data!N18 -> 0.0092388909 | M18: =Data!L18 -> 825.6 | N18: =Data!M18 -> 0.26301304 | O18: =Data!O18 -> 110.52895 | P18: =Data!P18 -> 0.612 | Q18: =Data!R18 -> -0.64 | R18: =Data!Q18 -> 0.78 | S18: =P18*F18 -> 0.612
A19: =Data!A19 -> 202305 | B19: 80450 | C19: =Data!F19 -> 25971 | D19: =IF(Data!D19="Mauritius", 1, 0) -> 1 | E19: =IF(Regression!A19>201500, 1, 0) -> 1 | F19: =D19*E19 -> 1 | G19: =Data!J19 -> 0.00097985463 | H19: =F19*G19 -> 0.00097985463 | I19: =Data!H19 -> 4.2408556 | J19: =Data!I19 -> 1.6160682 | K19: =(I19*G19)+(J19*(1-G19)) -> 1.6186401 | L19: =Data!N19 -> -0.046557304 | M19: =Data!L19 -> 825.6 | N19: =Data!M19 -> 0.31503695 | O19: =Data!O19 -> 108.46768 | P19: =Data!P19 -> 1 | Q19: =Data!R19 -> -0.64 | R19: =Data!Q19 -> 0.78 | S19: =P19*F19 -> 1
A20: =Data!A20 -> 202304 | B20: 80450 | C20: =Data!F20 -> 421 | D20: =IF(Data!D20="Mauritius", 1, 0) -> 1 | E20: =IF(Regression!A20>201500, 1, 0) -> 1 | F20: =D20*E20 -> 1 | G20: =Data!J20 -> 2.2257445e-05 | H20: =F20*G20 -> 2.2257445e-05 | I20: =Data!H20 -> 2.8445946 | J20: =Data!I20 -> 1.7850799 | K20: =(I20*G20)+(J20*(1-G20)) -> 1.7851035 | L20: =Data!N20 -> -0.091438326 | M20: =Data!L20 -> 825.6 | N20: =Data!M20 -> 0.2464332 | O20: =Data!O20 -> 106.80965 | P20: =Data!P20 -> 0.1039 | Q20: =Data!R20 -> -0.64 | R20: =Data!Q20 -> 0.78 | S20: =P20*F20 -> 0.1039
A21: =Data!A21 -> 202303 | B21: 80450 | C21: =Data!F21 -> 3986 | D21: =IF(Data!D21="Mauritius", 1, 0) -> 1 | E21: =IF(Regression!A21>201500, 1, 0) -> 1 | F21: =D21*E21 -> 1 | G21: =Data!J21 -> 0.00024389459 | H21: =F21*G21 -> 0.00024389459 | I21: =Data!H21 -> 2.6052288 | J21: =Data!I21 -> 1.6928368 | K21: =(I21*G21)+(J21*(1-G21)) -> 1.6930594 | L21: =Data!N21 -> -0.13013822 | M21: =Data!L21 -> 825.6 | N21: =Data!M21 -> 0.30663994 | O21: =Data!O21 -> 105.37997 | P21: =Data!P21 -> 0.7509 | Q21: =Data!R21 -> -0.64 | R21: =Data!Q21 -> 0.78 | S21: =P21*F21 -> 0.7509
A22: =Data!A22 -> 202302 | B22: 80450 | C22: =Data!F22 -> 17032 | D22: =IF(Data!D22="Mauritius", 1, 0) -> 1 | E22: =IF(Regression!A22>201500, 1, 0) -> 1 | F22: =D22*E22 -> 1 | G22: =Data!J22 -> 0.0017104202 | H22: =F22*G22 -> 0.0017104202 | I22: =Data!H22 -> 3.0501433 | J22: =Data!I22 -> 1.3625965 | K22: =(I22*G22)+(J22*(1-G22)) -> 1.3654829 | L22: =Data!N22 -> 0.29252683 | M22: =Data!L22 -> 825.6 | N22: =Data!M22 -> 0.29352903 | O22: =Data!O22 -> 120.99438 | P22: =Data!P22 -> 0.8874 | Q22: =Data!R22 -> -0.64 | R22: =Data!Q22 -> 0.78 | S22: =P22*F22 -> 0.8874
A23: =Data!A23 -> 202211 | B23: 80450 | C23: =Data!F23 -> 4549 | D23: =IF(Data!D23="Mauritius", 1, 0) -> 1 | E23: =IF(Regression!A23>201500, 1, 0) -> 1 | F23: =D23*E23 -> 1 | G23: =Data!J23 -> 0.00028359255 | H23: =F23*G23 -> 0.00028359255 | I23: =Data!H23 -> 2.4709397 | J23: =Data!I23 -> 1.3706627 | K23: =(I23*G23)+(J23*(1-G23)) -> 1.3709747 | L23: =Data!N23 -> 0.17672351 | M23: =Data!L23 -> 843.6 | N23: =Data!M23 -> 0.29648212 | O23: =Data!O23 -> 116.71629 | P23: =Data!P23 -> 0.9092 | Q23: =Data!R23 -> -0.62 | R23: =Data!Q23 -> 0.83 | S23: =P23*F23 -> 0.9092
A24: =Data!A24 -> 202210 | B24: 80450 | C24: =Data!F24 -> 23 | D24: =IF(Data!D24="Mauritius", 1, 0) -> 1 | E24: =IF(Regression!A24>201500, 1, 0) -> 1 | F24: =D24*E24 -> 1 | G24: =Data!J24 -> 1.3518735e-06 | H24: =F24*G24 -> 1.3518735e-06 | I24: =Data!H24 -> 2.5555556 | J24: =Data!I24 -> 1.3232739 | K24: =(I24*G24)+(J24*(1-G24)) -> 1.3232755 | L24: =Data!N24 -> 0.89259171 | M24: =Data!L24 -> 843.6 | N24: =Data!M24 -> 0.30671361 | O24: =Data!O24 -> 143.16241 | P24: =Data!P24 -> 0.0015 | Q24: =Data!R24 -> -0.62 | R24: =Data!Q24 -> 0.83 | S24: =P24*F24 -> 0.0015
A25: =Data!A25 -> 202209 | B25: 80450 | C25: =Data!F25 -> 39448 | D25: =IF(Data!D25="Mauritius", 1, 0) -> 1 | E25: =IF(Regression!A25>201500, 1, 0) -> 1 | F25: =D25*E25 -> 1 | G25: =Data!J25 -> 0.0015017903 | H25: =F25*G25 -> 0.0015017903 | I25: =Data!H25 -> 1.7316945 | J25: =Data!I25 -> 1.3487115 | K25: =(I25*G25)+(J25*(1-G25)) -> 1.3492866 | L25: =Data!N25 -> 0.5900547 | M25: =Data!L25 -> 843.6 | N25: =Data!M25 -> 0.50662738 | O25: =Data!O25 -> 131.98587 | P25: =Data!P25 -> 0.8456 | Q25: =Data!R25 -> -0.62 | R25: =Data!Q25 -> 0.83 | S25: =P25*F25 -> 0.8456
... A89: =Data!A89 -> 201302 | B89: 80450 | C89: =Data!F89 -> 860 | D89: =IF(Data!D89="Mauritius", 1, 0) -> 1 | E89: =IF(Regression!A89>201500, 1, 0) -> 0 | F89: =D89*E89 -> 0 | G89: =Data!J89 -> 8.5896177e-05 | H89: =F89*G89 -> 0 | I89: =Data!H89 -> 0.86 | J89: =Data!I89 -> 0.86039048 | K89: =(I89*G89)+(J89*(1-G89)) -> 0.86039045 | L89: =Data!N89 -> -0.77409819 | M89: =Data!L89 -> 713.7 | N89: =Data!M89 -> 0.11446615 | O89: =Data!O89 -> 81.590332 | P89: =Data!P89 -> 0.3549 | Q89: =Data!R89 -> -1.23 | R89: =Data!Q89 -> 0.94 | S89: =P89*F89 -> 0
A90: =Data!A90 -> 202506 | B90: 80450 | C90: =Data!F90 -> 12656 | D90: =IF(Data!D90="Mauritius", 1, 0) -> 0 | E90: =IF(Regression!A90>201500, 1, 0) -> 1 | F90: =D90*E90 -> 0 | G90: =Data!J90 -> 0.0008969365 | H90: =F90*G90 -> 0 | I90: =Data!H90 -> 2.4574757 | J90: =Data!I90 -> 1.4290057 | K90: =(I90*G90)+(J90*(1-G90)) -> 1.4299281 | L90: =Data!N90 -> -0.19286518 | N90: =Data!M90 -> 0.46758103 | O90: =Data!O90 -> 220.12001 | P90: =Data!P90 -> 0.116 | Q90: =Data!R90 -> -1.23 | R90: =Data!Q90 -> 0.94 | S90: =P90*F90 -> 0
A91: =Data!A91 -> 202505 | B91: 80450 | C91: =Data!F91 -> 11332 | D91: =IF(Data!D91="Mauritius", 1, 0) -> 0 | E91: =IF(Regression!A91>201500, 1, 0) -> 1 | F91: =D91*E91 -> 0 | G91: =Data!J91 -> 0.00039873751 | H91: =F91*G91 -> 0 | I91: =Data!H91 -> 2.208106 | J91: =Data!I91 -> 1.5528386 | K91: =(I91*G91)+(J91*(1-G91)) -> 1.5530998 | L91: =Data!N91 -> 0.83431979 | N91: =Data!M91 -> 0.76241863 | O91: =Data!O91 -> 165.22462 | P91: =Data!P91 -> 0.2263 | S91: =P91*F91 -> 0
A92: =Data!A92 -> 202504 | B92: 80450 | C92: =Data!F92 -> 2139 | D92: =IF(Data!D92="Mauritius", 1, 0) -> 0 | E92: =IF(Regression!A92>201500, 1, 0) -> 1 | F92: =D92*E92 -> 0 | G92: =Data!J92 -> 6.8728039e-05 | H92: =F92*G92 -> 0 | I92: =Data!H92 -> 2.7387964 | J92: =Data!I92 -> 1.6721507 | K92: =(I92*G92)+(J92*(1-G92)) -> 1.672224 | L92: =Data!N92 -> 1.3380927 | N92: =Data!M92 -> 0.42514426 | O92: =Data!O92 -> 140.5289 | P92: =Data!P92 -> 0.9912 | S92: =P92*F92 -> 0
A93: =Data!A93 -> 202503 | B93: 80450 | C93: =Data!F93 -> 16427 | D93: =IF(Data!D93="Mauritius", 1, 0) -> 0 | E93: =IF(Regression!A93>201500, 1, 0) -> 1 | F93: =D93*E93 -> 0 | G93: =Data!J93 -> 0.0010579223 | H93: =F93*G93 -> 0 | I93: =Data!H93 -> 1.8718095 | J93: =Data!I93 -> 1.5056713 | K93: =(I93*G93)+(J93*(1-G93)) -> 1.5060587 | L93: =Data!N93 -> 0.58232816 | N93: =Data!M93 -> 0.24915466 | O93: =Data!O93 -> 171.87291 | P93: =Data!P93 -> 1 | S93: =P93*F93 -> 0
A94: =Data!A94 -> 202502 | B94: 80450 | C94: =Data!F94 -> 101958 | D94: =IF(Data!D94="Mauritius", 1, 0) -> 0 | E94: =IF(Regression!A94>201500, 1, 0) -> 1 | F94: =D94*E94 -> 0 | G94: =Data!J94 -> 0.010646738 | H94: =F94*G94 -> 0 | I94: =Data!H94 -> 0.75777035 | J94: =Data!I94 -> 1.3750398 | K94: =(I94*G94)+(J94*(1-G94)) -> 1.3684679 | L94: =Data!N94 -> 0.37442787 | N94: =Data!M94 -> 0.20897937 | O94: =Data!O94 -> 136.20163 | P94: =Data!P94 -> 0.9401 | S94: =P94*F94 -> 0
A95: =Data!A95 -> 202501 | B95: 80450 | C95: =Data!F95 -> 18862 | D95: =IF(Data!D95="Mauritius", 1, 0) -> 0 | E95: =IF(Regression!A95>201500, 1, 0) -> 1 | F95: =D95*E95 -> 0 | G95: =Data!J95 -> 0.0025808563 | H95: =F95*G95 -> 0 | I95: =Data!H95 -> 2.1453594 | J95: =Data!I95 -> 1.2166639 | K95: =(I95*G95)+(J95*(1-G95)) -> 1.2190607 | L95: =Data!N95 -> 0.54749891 | N95: =Data!M95 -> 0.23840894 | O95: =Data!O95 -> 112.32622 | P95: =Data!P95 -> 0.2723 | S95: =P95*F95 -> 0
A96: =Data!A96 -> 202412 | B96: 80450 | C96: =Data!F96 -> 8426 | D96: =IF(Data!D96="Mauritius", 1, 0) -> 0 | E96: =IF(Regression!A96>201500, 1, 0) -> 1 | F96: =D96*E96 -> 0 | G96: =Data!J96 -> 0.00078498076 | H96: =F96*G96 -> 0 | I96: =Data!H96 -> 1.6645595 | J96: =Data!I96 -> 1.2264705 | K96: =(I96*G96)+(J96*(1-G96)) -> 1.2268144 | L96: =Data!N96 -> 1.0792568 | M96: =Data!L96 -> 833.3 | N96: =Data!M96 -> 0.19472842 | O96: =Data!O96 -> 141.90271 | P96: =Data!P96 -> 0.635 | S96: =P96*F96 -> 0
A97: =Data!A97 -> 202411 | B97: 80450 | C97: =Data!F97 -> 11405 | D97: =IF(Data!D97="Mauritius", 1, 0) -> 0 | E97: =IF(Regression!A97>201500, 1, 0) -> 1 | F97: =D97*E97 -> 0 | G97: =Data!J97 -> 0.0011857759 | H97: =F97*G97 -> 0 | I97: =Data!H97 -> 2.424017 | J97: =Data!I97 -> 1.1506152 | K97: =(I97*G97)+(J97*(1-G97)) -> 1.1521251 | L97: =Data!N97 -> 0.84872153 | M97: =Data!L97 -> 833.3 | N97: =Data!M97 -> 0.18260814 | O97: =Data!O97 -> 128.48177 | P97: =Data!P97 -> 0.1572 | S97: =P97*F97 -> 0
A98: =Data!A98 -> 202410 | B98: 80450 | C98: =Data!F98 -> 4962 | D98: =IF(Data!D98="Mauritius", 1, 0) -> 0 | E98: =IF(Regression!A98>201500, 1, 0) -> 1 | F98: =D98*E98 -> 0 | G98: =Data!J98 -> 0.00044280704 | H98: =F98*G98 -> 0 | I98: =Data!H98 -> 2.1564537 | J98: =Data!I98 -> 1.3245168 | K98: =(I98*G98)+(J98*(1-G98)) -> 1.3248852 | L98: =Data!N98 -> 2.2534002 | M98: =Data!L98 -> 833.3 | N98: =Data!M98 -> 0.2658588 | O98: =Data!O98 -> 130.68921 | P98: =Data!P98 -> 0.0366 | S98: =P98*F98 -> 0
A99: =Data!A99 -> 202409 | B99: 80450 | C99: =Data!F99 -> 7498 | D99: =IF(Data!D99="Mauritius", 1, 0) -> 0 | E99: =IF(Regression!A99>201500, 1, 0) -> 1 | F99: =D99*E99 -> 0 | G99: =Data!J99 -> 0.00099654651 | H99: =F99*G99 -> 0 | I99: =Data!H99 -> 2.5730954 | J99: =Data!I99 -> 1.4878749 | K99: =(I99*G99)+(J99*(1-G99)) -> 1.4889564 | L99: =Data!N99 -> 0.31389533 | M99: =Data!L99 -> 833.3 | N99: =Data!M99 -> 0.1691497 | O99: =Data!O99 -> 130.14188 | P99: =Data!P99 -> 0.1644 | S99: =P99*F99 -> 0
A100: =Data!A100 -> 202408 | B100: 80450 | C100: =Data!F100 -> 3560 | D100: =IF(Data!D100="Mauritius", 1, 0) -> 0 | E100: =IF(Regression!A100>201500, 1, 0) -> 1 | F100: =D100*E100 -> 0 | G100: =Data!J100 -> 0.00036645579 | H100: =F100*G100 -> 0 | I100: =Data!H100 -> 2.0331239 | J100: =Data!I100 -> 1.2541433 | K100: =(I100*G100)+(J100*(1-G100)) -> 1.2544288 | L100: =Data!N100 -> 0.26869939 | M100: =Data!L100 -> 833.3 | N100: =Data!M100 -> 0.22787695 | O100: =Data!O100 -> 140.76402 | P100: =Data!P100 -> 0.1446 | S100: =P100*F100 -> 0
A101: =Data!A101 -> 202407 | B101: 80450 | C101: =Data!F101 -> 12171 | D101: =IF(Data!D101="Mauritius", 1, 0) -> 0 | E101: =IF(Regression!A101>201500, 1, 0) -> 1 | F101: =D101*E101 -> 0 | G101: =Data!J101 -> 0.0013407467 | H101: =F101*G101 -> 0 | I101: =Data!H101 -> 1.975491 | J101: =Data!I101 -> 0.97456242 | K101: =(I101*G101)+(J101*(1-G101)) -> 0.97590441 | L101: =Data!N101 -> -0.063178926 | M101: =Data!L101 -> 833.3 | N101: =Data!M101 -> 0.16011824 | O101: =Data!O101 -> 92.394875 | P101: =Data!P101 -> 0.9206 | S101: =P101*F101 -> 0
A102: =Data!A102 -> 202406 | B102: 80450 | C102: =Data!F102 -> 2545 | D102: =IF(Data!D102="Mauritius", 1, 0) -> 0 | E102: =IF(Regression!A102>201500, 1, 0) -> 1 | F102: =D102*E102 -> 0 | G102: =Data!J102 -> 0.00017692473 | H102: =F102*G102 -> 0 | I102: =Data!H102 -> 0.90184266 | J102: =Data!I102 -> 1.6192706 | K102: =(I102*G102)+(J102*(1-G102)) -> 1.6191437 | L102: =Data!N102 -> 1.3084181 | M102: =Data!L102 -> 833.3 | N102: =Data!M102 -> 0.19021051 | O102: =Data!O102 -> 112.88141 | P102: =Data!P102 -> 1 | S102: =P102*F102 -> 0
A103: =Data!A103 -> 202405 | B103: 80450 | C103: =Data!F103 -> 28232 | D103: =IF(Data!D103="Mauritius", 1, 0) -> 0 | E103: =IF(Regression!A103>201500, 1, 0) -> 1 | F103: =D103*E103 -> 0 | G103: =Data!J103 -> 0.00096604674 | H103: =F103*G103 -> 0 | I103: =Data!H103 -> 2.413404 | J103: =Data!I103 -> 1.7477125 | K103: =(I103*G103)+(J103*(1-G103)) -> 1.7483556 | L103: =Data!N103 -> 2.929601 | M103: =Data!L103 -> 833.3 | N103: =Data!M103 -> 0.13457304 | O103: =Data!O103 -> 130.52187 | P103: =Data!P103 -> 0.7973 | S103: =P103*F103 -> 0
...
