Workbook

Sheet Data
A1: Period | B1: Trade Flow | C1: Reporter | D1: Partner | E1: Commodity Code | F1: Trade Value (US) | G1: Net Weight(kg) | H1: Export Prices (India) | I1: Export Prices (World) | J1: GPR_importer | K1: Producer Prices | L1: Export Share | M1: GPR_exporter | N1: GPR_world | O1: Import Share | P1: Pol Stab_importer | Q1: Pol Stab_exporter | U1: Source: Period, Trade Flow, Reporter, Partner, Commodity Code, Net Weight: UN comtrade: https://comtradeplus.un.org/
A2: 202506 | B2: M | C2: India | D2: Malawi | E2: 71360 | F2: 2374880 | G2: 3189740 | H2: =F2/G2 -> 0.74453717 | I2: 0.7465 | J2: 0.46758103 | L2: 0.93736358 | M2: 220.12001 | N2: =VLOOKUP(A2,$S$5:$T$158,2,FALSE) -> 220.12001 | O2: 0.0554 | U2: Source: Producer Prices: https://www.fao.org/faostat/en/#data/PP
A3: 202505 | B3: M | C3: India | D3: Malawi | E3: 71360 | F3: 2602564 | G3: 3247200 | H3: =F3/G3 -> 0.80147943 | I3: 0.8259 | J3: 0.76241863 | L3: 0.94205756 | M3: 165.22462 | N3: =VLOOKUP(A3,$S$5:$T$158,2,FALSE) -> 165.22462 | O3: 0.0368 | U3: Source: GPR_importer, exporter, world: https://www.matteoiacoviello.com/gpr.htm
A4: 202504 | B4: M | C4: India | D4: Malawi | E4: 71360 | F4: 2640494 | G4: 3262000 | H4: =F4/G4 -> 0.80947088 | I4: 0.8257 | J4: 0.42514426 | L4: 0.95744031 | M4: 140.5289 | N4: =VLOOKUP(A4,$S$5:$T$158,2,FALSE) -> 140.5289 | O4: 0.0333
A5: 202503 | B5: M | C5: India | D5: Malawi | E5: 71360 | F5: 620116 | G5: 833000 | H5: =F5/G5 -> 0.74443697 | I5: 0.8496 | J5: 0.24915466 | L5: 0.67451716 | M5: 171.87291 | N5: =VLOOKUP(A5,$S$5:$T$158,2,FALSE) -> 171.87291 | O5: 0.0251 | S5: 201301 | T5: 90.657494
A6: 202502 | B6: M | C6: India | D6: Malawi | E6: 71360 | F6: 1527395 | G6: 2053050 | H6: =F6/G6 -> 0.74396386 | I6: 0.7754 | J6: 0.20897937 | L6: 0.89075891 | M6: 136.20163 | N6: =VLOOKUP(A6,$S$5:$T$158,2,FALSE) -> 136.20163 | O6: 0.1006 | S6: 201302 | T6: 81.590332
A7: 202501 | B7: M | C7: India | D7: Malawi | E7: 71360 | F7: 7723174 | G7: 8934560 | H7: =F7/G7 -> 0.86441571 | I7: 0.8644 | J7: 0.23840894 | L7: 0.9817223 | M7: 112.32622 | N7: =VLOOKUP(A7,$S$5:$T$158,2,FALSE) -> 112.32622 | O7: 0.1594 | S7: 201303 | T7: 75.896721
A8: 202412 | B8: M | C8: India | D8: Malawi | E8: 71360 | F8: 9465712 | G8: 10586250 | H8: =F8/G8 -> 0.89415156 | I8: 0.8994 | J8: 0.19472842 | K8: 520.1 | L8: 0.98550885 | M8: 141.90271 | N8: =VLOOKUP(A8,$S$5:$T$158,2,FALSE) -> 141.90271 | O8: 0.0947 | S8: 201304 | T8: 95.107872
A9: 202411 | B9: M | C9: India | D9: Malawi | E9: 71360 | F9: 12683154 | G9: 13945500 | H9: =F9/G9 -> 0.90948005 | I9: 0.9147 | J9: 0.18260814 | K9: 520.1 | L9: 0.98028706 | M9: 128.48177 | N9: =VLOOKUP(A9,$S$5:$T$158,2,FALSE) -> 128.48177 | O9: 0.0754 | S9: 201305 | T9: 83.717316
A10: 202410 | B10: M | C10: India | D10: Malawi | E10: 71360 | F10: 16695451 | G10: 16992800 | H10: =F10/G10 -> 0.98250147 | I10: 0.9839 | J10: 0.2658588 | K10: 520.1 | L10: 0.99106846 | M10: 130.68921 | N10: =VLOOKUP(A10,$S$5:$T$158,2,FALSE) -> 130.68921 | O10: 0.0669 | S10: 201306 | T10: 82.973007
A11: 202409 | B11: M | C11: India | D11: Malawi | E11: 71360 | F11: 14571423 | G11: 13695000 | H11: =F11/G11 -> 1.0639958 | I11: 1.064 | J11: 0.1691497 | K11: 520.1 | L11: 0.97462856 | M11: 130.14188 | N11: =VLOOKUP(A11,$S$5:$T$158,2,FALSE) -> 130.14188 | O11: 0.0689 | S11: 201307 | T11: 73.975815
A12: 202408 | B12: M | C12: India | D12: Malawi | E12: 71360 | F12: 3240866 | G12: 2839010 | H12: =F12/G12 -> 1.1415479 | I12: 1.1499 | J12: 0.22787695 | K12: 520.1 | L12: 0.97976569 | M12: 140.76402 | N12: =VLOOKUP(A12,$S$5:$T$158,2,FALSE) -> 140.76402 | O12: 0.0287 | S12: 201308 | T12: 90.956749
A13: 202407 | B13: M | C13: India | D13: Malawi | E13: 71360 | F13: 1486642 | G13: 1074750 | H13: =F13/G13 -> 1.3832445 | I13: 1.4238 | J13: 0.16011824 | K13: 520.1 | L13: 0.87212721 | M13: 92.394875 | N13: =VLOOKUP(A13,$S$5:$T$158,2,FALSE) -> 92.394875 | O13: 0.0159 | S13: 201309 | T13: 100.45933
A14: 202406 | B14: M | C14: India | D14: Malawi | E14: 71360 | F14: 1925836 | G14: 1595970 | H14: =F14/G14 -> 1.2066868 | I14: 1.2453 | J14: 0.19021051 | K14: 520.1 | L14: 0.90124154 | M14: 112.88141 | N14: =VLOOKUP(A14,$S$5:$T$158,2,FALSE) -> 112.88141 | O14: 0.017 | S14: 201310 | T14: 72.953117
A15: 202405 | B15: M | C15: India | D15: Malawi | E15: 71360 | F15: 2257265 | G15: 1923240 | H15: =F15/G15 -> 1.1736783 | I15: 1.2331 | J15: 0.13457304 | K15: 520.1 | L15: 0.8300575 | M15: 130.52187 | N15: =VLOOKUP(A15,$S$5:$T$158,2,FALSE) -> 130.52187 | O15: 0.0294 | S15: 201311 | T15: 77.779022
A16: 202404 | B16: M | C16: India | D16: Malawi | E16: 71360 | F16: 5434472 | G16: 5560490 | H16: =F16/G16 -> 0.97733689 | I16: 0.9824 | J16: 0.24681982 | K16: 520.1 | L16: 0.98879146 | M16: 163.73634 | N16: =VLOOKUP(A16,$S$5:$T$158,2,FALSE) -> 163.73634 | O16: 0.0739 | S16: 201312 | T16: 70.37249
A17: 202403 | B17: M | C17: India | D17: Malawi | E17: 71360 | F17: 1358609 | G17: 1224980 | H17: =F17/G17 -> 1.1090867 | I17: 1.1387 | J17: 0.23973444 | K17: 520.1 | L17: 0.92399941 | M17: 133.21317 | N17: =VLOOKUP(A17,$S$5:$T$158,2,FALSE) -> 133.21317 | O17: 0.0251 | S17: 201401 | T17: 77.91597
A18: 202402 | B18: M | C18: India | D18: Malawi | E18: 71360 | F18: 2989384 | G18: 3150000 | H18: =F18/G18 -> 0.94901079 | I18: 0.9505 | J18: 0.21592619 | K18: 520.1 | L18: 0.99787332 | M18: 146.59818 | N18: =VLOOKUP(A18,$S$5:$T$158,2,FALSE) -> 146.59818 | O18: 0.0574 | S18: 201402 | T18: 69.003525
A19: 202401 | B19: M | C19: India | D19: Malawi | E19: 71360 | F19: 5517690 | G19: 5872900 | H19: =F19/G19 -> 0.9395171 | I19: 0.9506 | J19: 0.27558562 | K19: 520.1 | L19: 0.9635155 | M19: 160.16484 | N19: =VLOOKUP(A19,$S$5:$T$158,2,FALSE) -> 160.16484 | O19: 0.1091 | S19: 201403 | T19: 119.83855
A20: 202312 | B20: M | C20: India | D20: Malawi | E20: 71360 | F20: 4208236 | G20: 3864980 | H20: =F20/G20 -> 1.0888118 | I20: 1.0913 | J20: 0.22528322 | K20: 533.8 | L20: 0.98892992 | M20: 142.27946 | N20: =VLOOKUP(A20,$S$5:$T$158,2,FALSE) -> 142.27946 | O20: 0.0496 | P20: -0.64 | Q20: -0.24 | S20: 201404 | T20: 93.221542
A21: 202311 | B21: M | C21: India | D21: Malawi | E21: 71360 | F21: 9556578 | G21: 10575950 | H21: =F21/G21 -> 0.90361414 | I21: 0.9096 | J21: 0.25032857 | K21: 533.8 | L21: 0.98364769 | M21: 156.69614 | N21: =VLOOKUP(A21,$S$5:$T$158,2,FALSE) -> 156.69614 | O21: 0.0869 | P21: -0.64 | Q21: -0.24 | S21: 201405 | T21: 83.428856
A22: 202310 | B22: M | C22: India | D22: Malawi | E22: 71360 | F22: 15388599 | G22: 16341600 | H22: =F22/G22 -> 0.94168252 | I22: 0.9309 | J22: 0.22093509 | K22: 533.8 | L22: 0.98686928 | M22: 197.88701 | N22: =VLOOKUP(A22,$S$5:$T$158,2,FALSE) -> 197.88701 | O22: 0.0911 | P22: -0.64 | Q22: -0.24 | S22: 201406 | T22: 98.767105
A23: 202309 | B23: M | C23: India | D23: Malawi | E23: 71360 | F23: 4399603 | G23: 4975010 | H23: =F23/G23 -> 0.88434053 | I23: 0.8886 | J23: 0.45979792 | K23: 533.8 | L23: 0.94058474 | M23: 98.634811 | N23: =VLOOKUP(A23,$S$5:$T$158,2,FALSE) -> 98.634811 | O23: 0.0634 | P23: -0.64 | Q23: -0.24 | S23: 201407 | T23: 138.75395
A24: 202308 | B24: M | C24: India | D24: Malawi | E24: 71360 | F24: 1872852 | G24: 1900000 | H24: =F24/G24 -> 0.98571158 | I24: 0.6693 | J24: 0.3154957 | K24: 533.8 | L24: 0.87933434 | M24: 101.14118 | N24: =VLOOKUP(A24,$S$5:$T$158,2,FALSE) -> 101.14118 | O24: 0.0419 | P24: -0.64 | Q24: -0.24 | S24: 201408 | T24: 136.44559
A25: 202307 | B25: M | C25: India | D25: Malawi | E25: 71360 | F25: 182430 | G25: 350000 | H25: =F25/G25 -> 0.52122857 | I25: 0.2817 | J25: 0.21112767 | K25: 533.8 | L25: 0.64329011 | M25: 107.44878 | N25: =VLOOKUP(A25,$S$5:$T$158,2,FALSE) -> 107.44878 | O25: 0.0078 | P25: -0.64 | Q25: -0.24 | S25: 201409 | T25: 131.55666
A26: 202306 | B26: M | C26: India | D26: Malawi | E26: 71360 | F26: 1525373 | G26: 1547000 | H26: =F26/G26 -> 0.98602004 | I26: 1.0002 | J26: 0.26301304 | K26: 533.8 | L26: 0.96749197 | M26: 110.52895 | N26: =VLOOKUP(A26,$S$5:$T$158,2,FALSE) -> 110.52895 | O26: 0.0485 | P26: -0.64 | Q26: -0.24 | S26: 201410 | T26: 83.661003
A27: 202305 | B27: M | C27: India | D27: Malawi | E27: 71360 | F27: 2615546 | G27: 3375000 | H27: =F27/G27 -> 0.77497659 | I27: 0.8086 | J27: 0.31503695 | K27: 533.8 | L27: 0.88000869 | M27: 108.46768 | N27: =VLOOKUP(A27,$S$5:$T$158,2,FALSE) -> 108.46768 | O27: 0.0724 | P27: -0.64 | Q27: -0.24 | S27: 201411 | T27: 84.380051
A28: 202304 | B28: M | C28: India | D28: Malawi | E28: 71360 | F28: 778074 | G28: 1047440 | H28: =F28/G28 -> 0.74283396 | I28: 0.759 | J28: 0.2464332 | K28: 533.8 | L28: 0.91336747 | M28: 106.80965 | N28: =VLOOKUP(A28,$S$5:$T$158,2,FALSE) -> 106.80965 | O28: 0.0112 | P28: -0.64 | Q28: -0.24 | S28: 201412 | T28: 86.526222
A29: 202303 | B29: M | C29: India | D29: Malawi | E29: 71360 | F29: 818649 | G29: 1275090 | H29: =F29/G29 -> 0.64203233 | I29: 0.6755 | J29: 0.30663994 | K29: 533.8 | L29: 0.79755215 | M29: 105.37997 | N29: =VLOOKUP(A29,$S$5:$T$158,2,FALSE) -> 105.37997 | O29: 0.014 | P29: -0.64 | Q29: -0.24 | S29: 201501 | T29: 111.98569
A30: 202302 | B30: M | C30: India | D30: Malawi | E30: 71360 | F30: 2261945 | G30: 3800000 | H30: =F30/G30 -> 0.59524868 | I30: 0.6003 | J30: 0.29352903 | K30: 533.8 | L30: 0.95894375 | M30: 120.99438 | N30: =VLOOKUP(A30,$S$5:$T$158,2,FALSE) -> 120.99438 | O30: 0.0343 | P30: -0.64 | Q30: -0.24 | S30: 201502 | T30: 111.9247
A31: 202301 | B31: M | C31: India | D31: Malawi | E31: 71360 | F31: 3543458 | G31: 5270940 | H31: =F31/G31 -> 0.67226301 | I31: 0.6769 | J31: 0.19585544 | K31: 533.8 | L31: 0.94791958 | M31: 104.26704 | N31: =VLOOKUP(A31,$S$5:$T$158,2,FALSE) -> 104.26704 | O31: 0.0504 | P31: -0.64 | Q31: -0.24 | S31: 201503 | T31: 104.23527
... A125: 201304 | B125: M | C125: India | D125: Malawi | E125: 71360 | F125: 81223 | G125: 150000 | H125: =F125/G125 -> 0.54148667 | I125: 0.8805 | J125: 0.1460018 | K125: 646.4 | L125: 0.26274621 | M125: 95.107872 | N125: =VLOOKUP(A125,$S$5:$T$158,2,FALSE) -> 95.107872 | O125: 0.0027 | P125: -1.23 | Q125: -0.21 | S125: 202301 | T125: 104.26704
A126: 202506 | B126: M | C126: India | D126: United Rep. of Tanzania | E126: 71360 | F126: 1111108 | G126: 1746450 | H126: =F126/G126 -> 0.63620945 | I126: 0.6362 | J126: 0.46758103 | L126: 1 | M126: 220.12001 | N126: =VLOOKUP(A126,$S$5:$T$158,2,FALSE) -> 220.12001 | O126: 0.026 | S126: 202302 | T126: 120.99438
A127: 202505 | B127: M | C127: India | D127: United Rep. of Tanzania | E127: 71360 | F127: 3429659 | G127: 4805700 | H127: =F127/G127 -> 0.71366481 | I127: 0.7137 | J127: 0.76241863 | L127: 1 | M127: 165.22462 | N127: =VLOOKUP(A127,$S$5:$T$158,2,FALSE) -> 165.22462 | O127: 0.0485 | S127: 202303 | T127: 105.37997
A128: 202504 | B128: M | C128: India | D128: United Rep. of Tanzania | E128: 71360 | F128: 2330356 | G128: 3060450 | H128: =F128/G128 -> 0.76144227 | I128: 0.7614 | J128: 0.42514426 | L128: 1 | M128: 140.5289 | N128: =VLOOKUP(A128,$S$5:$T$158,2,FALSE) -> 140.5289 | O128: 0.0294 | S128: 202304 | T128: 106.80965
A129: 202503 | B129: M | C129: India | D129: United Rep. of Tanzania | E129: 71360 | F129: 449917 | G129: 566140 | H129: =F129/G129 -> 0.79470979 | I129: 0.7947 | J129: 0.24915466 | L129: 1 | M129: 171.87291 | N129: =VLOOKUP(A129,$S$5:$T$158,2,FALSE) -> 171.87291 | O129: 0.0182 | S129: 202305 | T129: 108.46768
A130: 202502 | B130: M | C130: India | D130: United Rep. of Tanzania | E130: 71360 | F130: 630155 | G130: 800170 | H130: =F130/G130 -> 0.7875264 | I130: 0.7875 | J130: 0.20897937 | L130: 1 | M130: 136.20163 | N130: =VLOOKUP(A130,$S$5:$T$158,2,FALSE) -> 136.20163 | O130: 0.0415 | S130: 202306 | T130: 110.52895
A131: 202501 | B131: M | C131: India | D131: United Rep. of Tanzania | E131: 71360 | F131: 19169112 | G131: 24234600 | H131: =F131/G131 -> 0.79098116 | I131: 0.792 | J131: 0.23840894 | L131: 0.99773456 | M131: 112.32622 | N131: =VLOOKUP(A131,$S$5:$T$158,2,FALSE) -> 112.32622 | O131: 0.3956 | S131: 202307 | T131: 107.44878
A132: 202412 | B132: M | C132: India | D132: United Rep. of Tanzania | E132: 71360 | F132: 40359742 | G132: 50145200 | H132: =F132/G132 -> 0.80485753 | I132: 0.8052 | J132: 0.19472842 | K132: 562.3 | L132: 0.99654491 | M132: 141.90271 | N132: =VLOOKUP(A132,$S$5:$T$158,2,FALSE) -> 141.90271 | O132: 0.4042 | S132: 202308 | T132: 101.14118
A133: 202411 | B133: M | C133: India | D133: United Rep. of Tanzania | E133: 71360 | F133: 60597963 | G133: 72278600 | H133: =F133/G133 -> 0.83839426 | I133: 0.8384 | J133: 0.18260814 | K133: 562.3 | L133: 1 | M133: 128.48177 | N133: =VLOOKUP(A133,$S$5:$T$158,2,FALSE) -> 128.48177 | O133: 0.3607 | S133: 202309 | T133: 98.634811
...

Sheet Regression
A1: Year | B1: Commodity Code | C1: Trade Value | D1: Country Dummy | E1: Post MoU Dummy | F1: MoU in Effect Dummy | G1: Export Share | H1: MoU * Export Share | I1: Export Prices (Country) | J1: Export Prices (World) | K1: Weighted Export Price | L1: GPR_importer | M1: Producer Prices | N1: GPR_exporter | O1: GPR_world | P1: Import Share | Q1: MoU * Import Share | R1: PS_exporter | S1: PS_importer
A2: =Data!A2 -> 202506 | B2: 71360 | C2: =Data!F2 -> 2374880 | D2: =IF(Data!D2="Malawi", 1, 0) -> 1 | E2: =IF(A2>202100, 1, 0) -> 1 | F2: =D2*E2 -> 1 | G2: =Data!L2 -> 0.93736358 | H2: =F2*G2 -> 0.93736358 | I2: =Data!H2 -> 0.74453717 | J2: =Data!I2 -> 0.7465 | K2: =(I2*G2)+(J2*(1-G2)) -> 0.74466012 | L2: =Data!J2 -> 0.46758103 | N2: =Data!M2 -> 220.12001 | O2: =Data!N2 -> 220.12001 | P2: =Data!O2 -> 0.0554 | Q2: =P2*F2 -> 0.0554
A3: =Data!A3 -> 202505 | B3: 71360 | C3: =Data!F3 -> 2602564 | D3: =IF(Data!D3="Malawi", 1, 0) -> 1 | E3: =IF(A3>202100, 1, 0) -> 1 | F3: =D3*E3 -> 1 | G3: =Data!L3 -> 0.94205756 | H3: =F3*G3 -> 0.94205756 | I3: =Data!H3 -> 0.80147943 | J3: =Data!I3 -> 0.8259 | K3: =(I3*G3)+(J3*(1-G3)) -> 0.80289442 | L3: =Data!J3 -> 0.76241863 | N3: =Data!M3 -> 165.22462 | O3: =Data!N3 -> 165.22462 | P3: =Data!O3 -> 0.0368 | Q3: =P3*F3 -> 0.0368
A4: =Data!A4 -> 202504 | B4: 71360 | C4: =Data!F4 -> 2640494 | D4: =IF(Data!D4="Malawi", 1, 0) -> 1 | E4: =IF(A4>202100, 1, 0) -> 1 | F4: =D4*E4 -> 1 | G4: =Data!L4 -> 0.95744031 | H4: =F4*G4 -> 0.95744031 | I4: =Data!H4 -> 0.80947088 | J4: =Data!I4 -> 0.8257 | K4: =(I4*G4)+(J4*(1-G4)) -> 0.81016158 | L4: =Data!J4 -> 0.42514426 | N4: =Data!M4 -> 140.5289 | O4: =Data!N4 -> 140.5289 | P4: =Data!O4 -> 0.0333 | Q4: =P4*F4 -> 0.0333
A5: =Data!A5 -> 202503 | B5: 71360 | C5: =Data!F5 -> 620116 | D5: =IF(Data!D5="Malawi", 1, 0) -> 1 | E5: =IF(A5>202100, 1, 0) -> 1 | F5: =D5*E5 -> 1 | G5: =Data!L5 -> 0.67451716 | H5: =F5*G5 -> 0.67451716 | I5: =Data!H5 -> 0.74443697 | J5: =Data!I5 -> 0.8496 | K5: =(I5*G5)+(J5*(1-G5)) -> 0.77866574 | L5: =Data!J5 -> 0.24915466 | N5: =Data!M5 -> 171.87291 | O5: =Data!N5 -> 171.87291 | P5: =Data!O5 -> 0.0251 | Q5: =P5*F5 -> 0.0251
A6: =Data!A6 -> 202502 | B6: 71360 | C6: =Data!F6 -> 1527395 | D6: =IF(Data!D6="Malawi", 1, 0) -> 1 | E6: =IF(A6>202100, 1, 0) -> 1 | F6: =D6*E6 -> 1 | G6: =Data!L6 -> 0.89075891 | H6: =F6*G6 -> 0.89075891 | I6: =Data!H6 -> 0.74396386 | J6: =Data!I6 -> 0.7754 | K6: =(I6*G6)+(J6*(1-G6)) -> 0.74739798 | L6: =Data!J6 -> 0.20897937 | N6: =Data!M6 -> 136.20163 | O6: =Data!N6 -> 136.20163 | P6: =Data!O6 -> 0.1006 | Q6: =P6*F6 -> 0.1006
A7: =Data!A7 -> 202501 | B7: 71360 | C7: =Data!F7 -> 7723174 | D7: =IF(Data!D7="Malawi", 1, 0) -> 1 | E7: =IF(A7>202100, 1, 0) -> 1 | F7: =D7*E7 -> 1 | G7: =Data!L7 -> 0.9817223 | H7: =F7*G7 -> 0.9817223 | I7: =Data!H7 -> 0.86441571 | J7: =Data!I7 -> 0.8644 | K7: =(I7*G7)+(J7*(1-G7)) -> 0.86441542 | L7: =Data!J7 -> 0.23840894 | N7: =Data!M7 -> 112.32622 | O7: =Data!N7 -> 112.32622 | P7: =Data!O7 -> 0.1594 | Q7: =P7*F7 -> 0.1594
A8: =Data!A8 -> 202412 | B8: 71360 | C8: =Data!F8 -> 9465712 | D8: =IF(Data!D8="Malawi", 1, 0) -> 1 | E8: =IF(A8>202100, 1, 0) -> 1 | F8: =D8*E8 -> 1 | G8: =Data!L8 -> 0.98550885 | H8: =F8*G8 -> 0.98550885 | I8: =Data!H8 -> 0.89415156 | J8: =Data!I8 -> 0.8994 | K8: =(I8*G8)+(J8*(1-G8)) -> 0.89422762 | L8: =Data!J8 -> 0.19472842 | M8: =Data!K8 -> 520.1 | N8: =Data!M8 -> 141.90271 | O8: =Data!N8 -> 141.90271 | P8: =Data!O8 -> 0.0947 | Q8: =P8*F8 -> 0.0947
A9: =Data!A9 -> 202411 | B9: 71360 | C9: =Data!F9 -> 12683154 | D9: =IF(Data!D9="Malawi", 1, 0) -> 1 | E9: =IF(A9>202100, 1, 0) -> 1 | F9: =D9*E9 -> 1 | G9: =Data!L9 -> 0.98028706 | H9: =F9*G9 -> 0.98028706 | I9: =Data!H9 -> 0.90948005 | J9: =Data!I9 -> 0.9147 | K9: =(I9*G9)+(J9*(1-G9)) -> 0.90958295 | L9: =Data!J9 -> 0.18260814 | M9: =Data!K9 -> 520.1 | N9: =Data!M9 -> 128.48177 | O9: =Data!N9 -> 128.48177 | P9: =Data!O9 -> 0.0754 | Q9: =P9*F9 -> 0.0754
A10: =Data!A10 -> 202410 | B10: 71360 | C10: =Data!F10 -> 16695451 | D10: =IF(Data!D10="Malawi", 1, 0) -> 1 | E10: =IF(A10>202100, 1, 0) -> 1 | F10: =D10*E10 -> 1 | G10: =Data!L10 -> 0.99106846 | H10: =F10*G10 -> 0.99106846 | I10: =Data!H10 -> 0.98250147 | J10: =Data!I10 -> 0.9839 | K10: =(I10*G10)+(J10*(1-G10)) -> 0.98251396 | L10: =Data!J10 -> 0.2658588 | M10: =Data!K10 -> 520.1 | N10: =Data!M10 -> 130.68921 | O10: =Data!N10 -> 130.68921 | P10: =Data!O10 -> 0.0669 | Q10: =P10*F10 -> 0.0669
A11: =Data!A11 -> 202409 | B11: 71360 | C11: =Data!F11 -> 14571423 | D11: =IF(Data!D11="Malawi", 1, 0) -> 1 | E11: =IF(A11>202100, 1, 0) -> 1 | F11: =D11*E11 -> 1 | G11: =Data!L11 -> 0.97462856 | H11: =F11*G11 -> 0.97462856 | I11: =Data!H11 -> 1.0639958 | J11: =Data!I11 -> 1.064 | K11: =(I11*G11)+(J11*(1-G11)) -> 1.0639959 | L11: =Data!J11 -> 0.1691497 | M11: =Data!K11 -> 520.1 | N11: =Data!M11 -> 130.14188 | O11: =Data!N11 -> 130.14188 | P11: =Data!O11 -> 0.0689 | Q11: =P11*F11 -> 0.0689
A12: =Data!A12 -> 202408 | B12: 71360 | C12: =Data!F12 -> 3240866 | D12: =IF(Data!D12="Malawi", 1, 0) -> 1 | E12: =IF(A12>202100, 1, 0) -> 1 | F12: =D12*E12 -> 1 | G12: =Data!L12 -> 0.97976569 | H12: =F12*G12 -> 0.97976569 | I12: =Data!H12 -> 1.1415479 | J12: =Data!I12 -> 1.1499 | K12: =(I12*G12)+(J12*(1-G12)) -> 1.1417169 | L12: =Data!J12 -> 0.22787695 | M12: =Data!K12 -> 520.1 | N12: =Data!M12 -> 140.76402 | O12: =Data!N12 -> 140.76402 | P12: =Data!O12 -> 0.0287 | Q12: =P12*F12 -> 0.0287
A13: =Data!A13 -> 202407 | B13: 71360 | C13: =Data!F13 -> 1486642 | D13: =IF(Data!D13="Malawi", 1, 0) -> 1 | E13: =IF(A13>202100, 1, 0) -> 1 | F13: =D13*E13 -> 1 | G13: =Data!L13 -> 0.87212721 | H13: =F13*G13 -> 0.87212721 | I13: =Data!H13 -> 1.3832445 | J13: =Data!I13 -> 1.4238 | K13: =(I13*G13)+(J13*(1-G13)) -> 1.3884304 | L13: =Data!J13 -> 0.16011824 | M13: =Data!K13 -> 520.1 | N13: =Data!M13 -> 92.394875 | O13: =Data!N13 -> 92.394875 | P13: =Data!O13 -> 0.0159 | Q13: =P13*F13 -> 0.0159
A14: =Data!A14 -> 202406 | B14: 71360 | C14: =Data!F14 -> 1925836 | D14: =IF(Data!D14="Malawi", 1, 0) -> 1 | E14: =IF(A14>202100, 1, 0) -> 1 | F14: =D14*E14 -> 1 | G14: =Data!L14 -> 0.90124154 | H14: =F14*G14 -> 0.90124154 | I14: =Data!H14 -> 1.2066868 | J14: =Data!I14 -> 1.2453 | K14: =(I14*G14)+(J14*(1-G14)) -> 1.2105002 | L14: =Data!J14 -> 0.19021051 | M14: =Data!K14 -> 520.1 | N14: =Data!M14 -> 112.88141 | O14: =Data!N14 -> 112.88141 | P14: =Data!O14 -> 0.017 | Q14: =P14*F14 -> 0.017
A15: =Data!A15 -> 202405 | B15: 71360 | C15: =Data!F15 -> 2257265 | D15: =IF(Data!D15="Malawi", 1, 0) -> 1 | E15: =IF(A15>202100, 1, 0) -> 1 | F15: =D15*E15 -> 1 | G15: =Data!L15 -> 0.8300575 | H15: =F15*G15 -> 0.8300575 | I15: =Data!H15 -> 1.1736783 | J15: =Data!I15 -> 1.2331 | K15: =(I15*G15)+(J15*(1-G15)) -> 1.1837765 | L15: =Data!J15 -> 0.13457304 | M15: =Data!K15 -> 520.1 | N15: =Data!M15 -> 130.52187 | O15: =Data!N15 -> 130.52187 | P15: =Data!O15 -> 0.0294 | Q15: =P15*F15 -> 0.0294
A16: =Data!A16 -> 202404 | B16: 71360 | C16: =Data!F16 -> 5434472 | D16: =IF(Data!D16="Malawi", 1, 0) -> 1 | E16: =IF(A16>202100, 1, 0) -> 1 | F16: =D16*E16 -> 1 | G16: =Data!L16 -> 0.98879146 | H16: =F16*G16 -> 0.98879146 | I16: =Data!H16 -> 0.97733689 | J16: =Data!I16 -> 0.9824 | K16: =(I16*G16)+(J16*(1-G16)) -> 0.97739364 | L16: =Data!J16 -> 0.24681982 | M16: =Data!K16 -> 520.1 | N16: =Data!M16 -> 163.73634 | O16: =Data!N16 -> 163.73634 | P16: =Data!O16 -> 0.0739 | Q16: =P16*F16 -> 0.0739
A17: =Data!A17 -> 202403 | B17: 71360 | C17: =Data!F17 -> 1358609 | D17: =IF(Data!D17="Malawi", 1, 0) -> 1 | E17: =IF(A17>202100, 1, 0) -> 1 | F17: =D17*E17 -> 1 | G17: =Data!L17 -> 0.92399941 | H17: =F17*G17 -> 0.92399941 | I17: =Data!H17 -> 1.1090867 | J17: =Data!I17 -> 1.1387 | K17: =(I17*G17)+(J17*(1-G17)) -> 1.1113373 | L17: =Data!J17 -> 0.23973444 | M17: =Data!K17 -> 520.1 | N17: =Data!M17 -> 133.21317 | O17: =Data!N17 -> 133.21317 | P17: =Data!O17 -> 0.0251 | Q17: =P17*F17 -> 0.0251
A18: =Data!A18 -> 202402 | B18: 71360 | C18: =Data!F18 -> 2989384 | D18: =IF(Data!D18="Malawi", 1, 0) -> 1 | E18: =IF(A18>202100, 1, 0) -> 1 | F18: =D18*E18 -> 1 | G18: =Data!L18 -> 0.99787332 | H18: =F18*G18 -> 0.99787332 | I18: =Data!H18 -> 0.94901079 | J18: =Data!I18 -> 0.9505 | K18: =(I18*G18)+(J18*(1-G18)) -> 0.94901396 | L18: =Data!J18 -> 0.21592619 | M18: =Data!K18 -> 520.1 | N18: =Data!M18 -> 146.59818 | O18: =Data!N18 -> 146.59818 | P18: =Data!O18 -> 0.0574 | Q18: =P18*F18 -> 0.0574
A19: =Data!A19 -> 202401 | B19: 71360 | C19: =Data!F19 -> 5517690 | D19: =IF(Data!D19="Malawi", 1, 0) -> 1 | E19: =IF(A19>202100, 1, 0) -> 1 | F19: =D19*E19 -> 1 | G19: =Data!L19 -> 0.9635155 | H19: =F19*G19 -> 0.9635155 | I19: =Data!H19 -> 0.9395171 | J19: =Data!I19 -> 0.9506 | K19: =(I19*G19)+(J19*(1-G19)) -> 0.93992146 | L19: =Data!J19 -> 0.27558562 | M19: =Data!K19 -> 520.1 | N19: =Data!M19 -> 160.16484 | O19: =Data!N19 -> 160.16484 | P19: =Data!O19 -> 0.1091 | Q19: =P19*F19 -> 0.1091
A20: =Data!A20 -> 202312 | B20: 71360 | C20: =Data!F20 -> 4208236 | D20: =IF(Data!D20="Malawi", 1, 0) -> 1 | E20: =IF(A20>202100, 1, 0) -> 1 | F20: =D20*E20 -> 1 | G20: =Data!L20 -> 0.98892992 | H20: =F20*G20 -> 0.98892992 | I20: =Data!H20 -> 1.0888118 | J20: =Data!I20 -> 1.0913 | K20: =(I20*G20)+(J20*(1-G20)) -> 1.0888394 | L20: =Data!J20 -> 0.22528322 | M20: =Data!K20 -> 533.8 | N20: =Data!M20 -> 142.27946 | O20: =Data!N20 -> 142.27946 | P20: =Data!O20 -> 0.0496 | Q20: =P20*F20 -> 0.0496 | R20: =Data!Q20 -> -0.24 | S20: =Data!P20 -> -0.64
A21: =Data!A21 -> 202311 | B21: 71360 | C21: =Data!F21 -> 9556578 | D21: =IF(Data!D21="Malawi", 1, 0) -> 1 | E21: =IF(A21>202100, 1, 0) -> 1 | F21: =D21*E21 -> 1 | G21: =Data!L21 -> 0.98364769 | H21: =F21*G21 -> 0.98364769 | I21: =Data!H21 -> 0.90361414 | J21: =Data!I21 -> 0.9096 | K21: =(I21*G21)+(J21*(1-G21)) -> 0.90371203 | L21: =Data!J21 -> 0.25032857 | M21: =Data!K21 -> 533.8 | N21: =Data!M21 -> 156.69614 | O21: =Data!N21 -> 156.69614 | P21: =Data!O21 -> 0.0869 | Q21: =P21*F21 -> 0.0869 | R21: =Data!Q21 -> -0.24 | S21: =Data!P21 -> -0.64
A22: =Data!A22 -> 202310 | B22: 71360 | C22: =Data!F22 -> 15388599 | D22: =IF(Data!D22="Malawi", 1, 0) -> 1 | E22: =IF(A22>202100, 1, 0) -> 1 | F22: =D22*E22 -> 1 | G22: =Data!L22 -> 0.98686928 | H22: =F22*G22 -> 0.98686928 | I22: =Data!H22 -> 0.94168252 | J22: =Data!I22 -> 0.9309 | K22: =(I22*G22)+(J22*(1-G22)) -> 0.94154093 | L22: =Data!J22 -> 0.22093509 | M22: =Data!K22 -> 533.8 | N22: =Data!M22 -> 197.88701 | O22: =Data!N22 -> 197.88701 | P22: =Data!O22 -> 0.0911 | Q22: =P22*F22 -> 0.0911 | R22: =Data!Q22 -> -0.24 | S22: =Data!P22 -> -0.64
A23: =Data!A23 -> 202309 | B23: 71360 | C23: =Data!F23 -> 4399603 | D23: =IF(Data!D23="Malawi", 1, 0) -> 1 | E23: =IF(A23>202100, 1, 0) -> 1 | F23: =D23*E23 -> 1 | G23: =Data!L23 -> 0.94058474 | H23: =F23*G23 -> 0.94058474 | I23: =Data!H23 -> 0.88434053 | J23: =Data!I23 -> 0.8886 | K23: =(I23*G23)+(J23*(1-G23)) -> 0.88459361 | L23: =Data!J23 -> 0.45979792 | M23: =Data!K23 -> 533.8 | N23: =Data!M23 -> 98.634811 | O23: =Data!N23 -> 98.634811 | P23: =Data!O23 -> 0.0634 | Q23: =P23*F23 -> 0.0634 | R23: =Data!Q23 -> -0.24 | S23: =Data!P23 -> -0.64
A24: =Data!A24 -> 202308 | B24: 71360 | C24: =Data!F24 -> 1872852 | D24: =IF(Data!D24="Malawi", 1, 0) -> 1 | E24: =IF(A24>202100, 1, 0) -> 1 | F24: =D24*E24 -> 1 | G24: =Data!L24 -> 0.87933434 | H24: =F24*G24 -> 0.87933434 | I24: =Data!H24 -> 0.98571158 | J24: =Data!I24 -> 0.6693 | K24: =(I24*G24)+(J24*(1-G24)) -> 0.94753157 | L24: =Data!J24 -> 0.3154957 | M24: =Data!K24 -> 533.8 | N24: =Data!M24 -> 101.14118 | O24: =Data!N24 -> 101.14118 | P24: =Data!O24 -> 0.0419 | Q24: =P24*F24 -> 0.0419 | R24: =Data!Q24 -> -0.24 | S24: =Data!P24 -> -0.64
A25: =Data!A25 -> 202307 | B25: 71360 | C25: =Data!F25 -> 182430 | D25: =IF(Data!D25="Malawi", 1, 0) -> 1 | E25: =IF(A25>202100, 1, 0) -> 1 | F25: =D25*E25 -> 1 | G25: =Data!L25 -> 0.64329011 | H25: =F25*G25 -> 0.64329011 | I25: =Data!H25 -> 0.52122857 | J25: =Data!I25 -> 0.2817 | K25: =(I25*G25)+(J25*(1-G25)) -> 0.43578636 | L25: =Data!J25 -> 0.21112767 | M25: =Data!K25 -> 533.8 | N25: =Data!M25 -> 107.44878 | O25: =Data!N25 -> 107.44878 | P25: =Data!O25 -> 0.0078 | Q25: =P25*F25 -> 0.0078 | R25: =Data!Q25 -> -0.24 | S25: =Data!P25 -> -0.64
A26: =Data!A26 -> 202306 | B26: 71360 | C26: =Data!F26 -> 1525373 | D26: =IF(Data!D26="Malawi", 1, 0) -> 1 | E26: =IF(A26>202100, 1, 0) -> 1 | F26: =D26*E26 -> 1 | G26: =Data!L26 -> 0.96749197 | H26: =F26*G26 -> 0.96749197 | I26: =Data!H26 -> 0.98602004 | J26: =Data!I26 -> 1.0002 | K26: =(I26*G26)+(J26*(1-G26)) -> 0.986481 | L26: =Data!J26 -> 0.26301304 | M26: =Data!K26 -> 533.8 | N26: =Data!M26 -> 110.52895 | O26: =Data!N26 -> 110.52895 | P26: =Data!O26 -> 0.0485 | Q26: =P26*F26 -> 0.0485 | R26: =Data!Q26 -> -0.24 | S26: =Data!P26 -> -0.64
A27: =Data!A27 -> 202305 | B27: 71360 | C27: =Data!F27 -> 2615546 | D27: =IF(Data!D27="Malawi", 1, 0) -> 1 | E27: =IF(A27>202100, 1, 0) -> 1 | F27: =D27*E27 -> 1 | G27: =Data!L27 -> 0.88000869 | H27: =F27*G27 -> 0.88000869 | I27: =Data!H27 -> 0.77497659 | J27: =Data!I27 -> 0.8086 | K27: =(I27*G27)+(J27*(1-G27)) -> 0.77901111 | L27: =Data!J27 -> 0.31503695 | M27: =Data!K27 -> 533.8 | N27: =Data!M27 -> 108.46768 | O27: =Data!N27 -> 108.46768 | P27: =Data!O27 -> 0.0724 | Q27: =P27*F27 -> 0.0724 | R27: =Data!Q27 -> -0.24 | S27: =Data!P27 -> -0.64
A28: =Data!A28 -> 202304 | B28: 71360 | C28: =Data!F28 -> 778074 | D28: =IF(Data!D28="Malawi", 1, 0) -> 1 | E28: =IF(A28>202100, 1, 0) -> 1 | F28: =D28*E28 -> 1 | G28: =Data!L28 -> 0.91336747 | H28: =F28*G28 -> 0.91336747 | I28: =Data!H28 -> 0.74283396 | J28: =Data!I28 -> 0.759 | K28: =(I28*G28)+(J28*(1-G28)) -> 0.74423446 | L28: =Data!J28 -> 0.2464332 | M28: =Data!K28 -> 533.8 | N28: =Data!M28 -> 106.80965 | O28: =Data!N28 -> 106.80965 | P28: =Data!O28 -> 0.0112 | Q28: =P28*F28 -> 0.0112 | R28: =Data!Q28 -> -0.24 | S28: =Data!P28 -> -0.64
A29: =Data!A29 -> 202303 | B29: 71360 | C29: =Data!F29 -> 818649 | D29: =IF(Data!D29="Malawi", 1, 0) -> 1 | E29: =IF(A29>202100, 1, 0) -> 1 | F29: =D29*E29 -> 1 | G29: =Data!L29 -> 0.79755215 | H29: =F29*G29 -> 0.79755215 | I29: =Data!H29 -> 0.64203233 | J29: =Data!I29 -> 0.6755 | K29: =(I29*G29)+(J29*(1-G29)) -> 0.64880779 | L29: =Data!J29 -> 0.30663994 | M29: =Data!K29 -> 533.8 | N29: =Data!M29 -> 105.37997 | O29: =Data!N29 -> 105.37997 | P29: =Data!O29 -> 0.014 | Q29: =P29*F29 -> 0.014 | R29: =Data!Q29 -> -0.24 | S29: =Data!P29 -> -0.64
A30: =Data!A30 -> 202302 | B30: 71360 | C30: =Data!F30 -> 2261945 | D30: =IF(Data!D30="Malawi", 1, 0) -> 1 | E30: =IF(A30>202100, 1, 0) -> 1 | F30: =D30*E30 -> 1 | G30: =Data!L30 -> 0.95894375 | H30: =F30*G30 -> 0.95894375 | I30: =Data!H30 -> 0.59524868 | J30: =Data!I30 -> 0.6003 | K30: =(I30*G30)+(J30*(1-G30)) -> 0.59545607 | L30: =Data!J30 -> 0.29352903 | M30: =Data!K30 -> 533.8 | N30: =Data!M30 -> 120.99438 | O30: =Data!N30 -> 120.99438 | P30: =Data!O30 -> 0.0343 | Q30: =P30*F30 -> 0.0343 | R30: =Data!Q30 -> -0.24 | S30: =Data!P30 -> -0.64
A31: =Data!A31 -> 202301 | B31: 71360 | C31: =Data!F31 -> 3543458 | D31: =IF(Data!D31="Malawi", 1, 0) -> 1 | E31: =IF(A31>202100, 1, 0) -> 1 | F31: =D31*E31 -> 1 | G31: =Data!L31 -> 0.94791958 | H31: =F31*G31 -> 0.94791958 | I31: =Data!H31 -> 0.67226301 | J31: =Data!I31 -> 0.6769 | K31: =(I31*G31)+(J31*(1-G31)) -> 0.67250451 | L31: =Data!J31 -> 0.19585544 | M31: =Data!K31 -> 533.8 | N31: =Data!M31 -> 104.26704 | O31: =Data!N31 -> 104.26704 | P31: =Data!O31 -> 0.0504 | Q31: =P31*F31 -> 0.0504 | R31: =Data!Q31 -> -0.24 | S31: =Data!P31 -> -0.64
... A125: =Data!A125 -> 201304 | B125: 71360 | C125: =Data!F125 -> 81223 | D125: =IF(Data!D125="Malawi", 1, 0) -> 1 | E125: =IF(A125>202100, 1, 0) -> 0 | F125: =D125*E125 -> 0 | G125: =Data!L125 -> 0.26274621 | H125: =F125*G125 -> 0 | I125: =Data!H125 -> 0.54148667 | J125: =Data!I125 -> 0.8805 | K125: =(I125*G125)+(J125*(1-G125)) -> 0.79142553 | L125: =Data!J125 -> 0.1460018 | M125: =Data!K125 -> 646.4 | N125: =Data!M125 -> 95.107872 | O125: =Data!N125 -> 95.107872 | P125: =Data!O125 -> 0.0027 | Q125: =P125*F125 -> 0 | R125: =Data!Q125 -> -0.21 | S125: =Data!P125 -> -1.23
A126: =Data!A126 -> 202506 | B126: 71360 | C126: =Data!F126 -> 1111108 | D126: =IF(Data!D126="Malawi", 1, 0) -> 0 | E126: =IF(A126>202100, 1, 0) -> 1 | F126: =D126*E126 -> 0 | G126: =Data!L126 -> 1 | H126: =F126*G126 -> 0 | I126: =Data!H126 -> 0.63620945 | J126: =Data!I126 -> 0.6362 | K126: =(I126*G126)+(J126*(1-G126)) -> 0.63620945 | L126: =Data!J126 -> 0.46758103 | N126: =Data!M126 -> 220.12001 | O126: =Data!N126 -> 220.12001 | P126: =Data!O126 -> 0.026 | Q126: =P126*F126 -> 0
A127: =Data!A127 -> 202505 | B127: 71360 | C127: =Data!F127 -> 3429659 | D127: =IF(Data!D127="Malawi", 1, 0) -> 0 | E127: =IF(A127>202100, 1, 0) -> 1 | F127: =D127*E127 -> 0 | G127: =Data!L127 -> 1 | H127: =F127*G127 -> 0 | I127: =Data!H127 -> 0.71366481 | J127: =Data!I127 -> 0.7137 | K127: =(I127*G127)+(J127*(1-G127)) -> 0.71366481 | L127: =Data!J127 -> 0.76241863 | N127: =Data!M127 -> 165.22462 | O127: =Data!N127 -> 165.22462 | P127: =Data!O127 -> 0.0485 | Q127: =P127*F127 -> 0
A128: =Data!A128 -> 202504 | B128: 71360 | C128: =Data!F128 -> 2330356 | D128: =IF(Data!D128="Malawi", 1, 0) -> 0 | E128: =IF(A128>202100, 1, 0) -> 1 | F128: =D128*E128 -> 0 | G128: =Data!L128 -> 1 | H128: =F128*G128 -> 0 | I128: =Data!H128 -> 0.76144227 | J128: =Data!I128 -> 0.7614 | K128: =(I128*G128)+(J128*(1-G128)) -> 0.76144227 | L128: =Data!J128 -> 0.42514426 | N128: =Data!M128 -> 140.5289 | O128: =Data!N128 -> 140.5289 | P128: =Data!O128 -> 0.0294 | Q128: =P128*F128 -> 0
A129: =Data!A129 -> 202503 | B129: 71360 | C129: =Data!F129 -> 449917 | D129: =IF(Data!D129="Malawi", 1, 0) -> 0 | E129: =IF(A129>202100, 1, 0) -> 1 | F129: =D129*E129 -> 0 | G129: =Data!L129 -> 1 | H129: =F129*G129 -> 0 | I129: =Data!H129 -> 0.79470979 | J129: =Data!I129 -> 0.7947 | K129: =(I129*G129)+(J129*(1-G129)) -> 0.79470979 | L129: =Data!J129 -> 0.24915466 | N129: =Data!M129 -> 171.87291 | O129: =Data!N129 -> 171.87291 | P129: =Data!O129 -> 0.0182 | Q129: =P129*F129 -> 0
A130: =Data!A130 -> 202502 | B130: 71360 | C130: =Data!F130 -> 630155 | D130: =IF(Data!D130="Malawi", 1, 0) -> 0 | E130: =IF(A130>202100, 1, 0) -> 1 | F130: =D130*E130 -> 0 | G130: =Data!L130 -> 1 | H130: =F130*G130 -> 0 | I130: =Data!H130 -> 0.7875264 | J130: =Data!I130 -> 0.7875 | K130: =(I130*G130)+(J130*(1-G130)) -> 0.7875264 | L130: =Data!J130 -> 0.20897937 | N130: =Data!M130 -> 136.20163 | O130: =Data!N130 -> 136.20163 | P130: =Data!O130 -> 0.0415 | Q130: =P130*F130 -> 0
A131: =Data!A131 -> 202501 | B131: 71360 | C131: =Data!F131 -> 19169112 | D131: =IF(Data!D131="Malawi", 1, 0) -> 0 | E131: =IF(A131>202100, 1, 0) -> 1 | F131: =D131*E131 -> 0 | G131: =Data!L131 -> 0.99773456 | H131: =F131*G131 -> 0 | I131: =Data!H131 -> 0.79098116 | J131: =Data!I131 -> 0.792 | K131: =(I131*G131)+(J131*(1-G131)) -> 0.79098347 | L131: =Data!J131 -> 0.23840894 | N131: =Data!M131 -> 112.32622 | O131: =Data!N131 -> 112.32622 | P131: =Data!O131 -> 0.3956 | Q131: =P131*F131 -> 0
A132: =Data!A132 -> 202412 | B132: 71360 | C132: =Data!F132 -> 40359742 | D132: =IF(Data!D132="Malawi", 1, 0) -> 0 | E132: =IF(A132>202100, 1, 0) -> 1 | F132: =D132*E132 -> 0 | G132: =Data!L132 -> 0.99654491 | H132: =F132*G132 -> 0 | I132: =Data!H132 -> 0.80485753 | J132: =Data!I132 -> 0.8052 | K132: =(I132*G132)+(J132*(1-G132)) -> 0.80485872 | L132: =Data!J132 -> 0.19472842 | M132: =Data!K132 -> 562.3 | N132: =Data!M132 -> 141.90271 | O132: =Data!N132 -> 141.90271 | P132: =Data!O132 -> 0.4042 | Q132: =P132*F132 -> 0
A133: =Data!A133 -> 202411 | B133: 71360 | C133: =Data!F133 -> 60597963 | D133: =IF(Data!D133="Malawi", 1, 0) -> 0 | E133: =IF(A133>202100, 1, 0) -> 1 | F133: =D133*E133 -> 0 | G133: =Data!L133 -> 1 | H133: =F133*G133 -> 0 | I133: =Data!H133 -> 0.83839426 | J133: =Data!I133 -> 0.8384 | K133: =(I133*G133)+(J133*(1-G133)) -> 0.83839426 | L133: =Data!J133 -> 0.18260814 | M133: =Data!K133 -> 562.3 | N133: =Data!M133 -> 128.48177 | O133: =Data!N133 -> 128.48177 | P133: =Data!O133 -> 0.3607 | Q133: =P133*F133 -> 0
...
